<?xml version="1.0" encoding="UTF-8"?> 									<!--Versão com erros consertados-->
<sdf version='1.6'>
  <model name='vant_4_aerod'>
    <link name='Main_Body'>
      <pose frame=''>0 0 0 0 -0 0</pose>
      <inertial>
        <pose frame=''>0.06684 0 0.005392 0 -0 0</pose>
        <mass>7.0</mass>
        <inertia>
          <ixx>0.1489</ixx>
          <ixy>0.0001</ixy>
          <ixz>-0.0189</ixz>
          <iyy>0.1789</iyy>
          <iyz>-0.000029</iyz>
          <izz>0.3011</izz>
        </inertia>
      </inertial>
      <collision name='Main_Body_collision'>    
        <pose frame=''>0 0 0 0 -0 0</pose>
        <geometry>
          <mesh>
            <scale>1 1 1</scale>
            <uri>model://vant_4_aerod/meshes/Main_Body.STL</uri>
          </mesh>
        </geometry>
      </collision>
      <visual name='Main_Body_visual'>
        <pose frame=''>0 0 0 0 -0 0</pose>
       <material>
          <ambient>0 0 0.75 1</ambient>
          <diffuse>0 0 0.75 1</diffuse>
        </material>
        <geometry>
          <mesh>
            <scale>1 1 1</scale>
            <uri>model://vant_4_aerod/meshes/Main_Body.STL</uri>
          </mesh>
        </geometry>
      </visual>
    </link>
 <!--  <link name="fuselagem_aerodcenter">
            <pose>-0.005 0 0.0326 0 0 0</pose>
            <inertial>
                <mass>0.000000001</mass>
                <pose>0 0 0 0 0 0</pose>
                <inertia>
                    <ixx>0.0000001</ixx>
                    <ixy>0</ixy>
                    <ixz>0</ixz>
                    <iyy>0.0000001</iyy>
                    <iyz>0</iyz>
                    <izz>0.0000001</izz>
                </inertia>
            </inertial>
        </link>									-->										
    <link name='Aileron_L'>
      <pose frame=''>0.015778 0.35336 0.10425 0.082272 0.12555 -0.000197</pose>
      <inertial>
        <pose frame=''>0 0 0 0 -0 0</pose>
        <mass>0.0001</mass>
        <inertia>
          <ixx>0.00000001</ixx>
          <ixy>0</ixy>
          <ixz>0.0000000</ixz>
          <iyy>0.00000001</iyy>
          <iyz>0.0000000</iyz>
          <izz>0.00000001</izz>
        </inertia>
      </inertial>
      <collision name='Aileron_L_collision'>
        <pose frame=''>0 0 0 0 -0 0</pose>
        <geometry>
          <mesh>
            <scale>1 1 1</scale>
            <uri>model://vant_4_aerod/meshes/Aileron_L.STL</uri>
          </mesh>
        </geometry>
      </collision>
      <visual name='Aileron_L_visual'>
        <pose frame=''>0 0 0 0 -0 0</pose>
        <material>
          <ambient>0 0 0.75 1</ambient>
          <diffuse>0 0 0.75 1</diffuse>
        </material>
        <geometry>
          <mesh>
            <scale>1 1 1</scale>
            <uri>model://vant_4_aerod/meshes/Aileron_L.STL</uri>
          </mesh>
        </geometry>
      </visual>
    </link>
    <joint name='Aileron_L_joint_name' type='revolute'>
      <child>Aileron_L</child>
      <parent>Main_Body</parent>
      <axis>
        <xyz>0.010487 0.996616 0.081532</xyz>
        <limit>
          <lower>-1.57</lower>
          <upper>1.57</upper>
          <effort>200</effort>
          <velocity>100</velocity>
        </limit>
        <dynamics>
          <spring_reference>0</spring_reference>
          <spring_stiffness>0</spring_stiffness>
        </dynamics>
        <use_parent_model_frame>1</use_parent_model_frame>
      </axis>
    </joint>
    <link name='Aileron_R'>
      <pose frame=''>0.016127 -0.35273 0.10416 -0.082286 0.057788 0.000195</pose>
      <inertial>
        <pose frame=''>0 0 0 0 -0 0</pose>
        <mass>0.0001</mass>
        <inertia>
          <ixx>0.00000001</ixx>
          <ixy>0</ixy>
          <ixz>0.0000000</ixz>
          <iyy>0.00000001</iyy>
          <iyz>0.0000000</iyz>
          <izz>0.00000001</izz>
        </inertia>
      </inertial>
      <collision name='Aileron_R_collision'>
        <pose frame=''>0 0 0 0 -0 0</pose>
        <geometry>
          <mesh>
            <scale>1 1 1</scale>
            <uri>model://vant_4_aerod/meshes/Aileron_R.STL</uri>
          </mesh>
        </geometry>
      </collision>
      <visual name='Aileron_R_visual'>
        <pose frame=''>0 0 0 0 -0 0</pose>
        <material>
          <ambient>0 0 0.75 1</ambient>
          <diffuse>0 0 0.75 1</diffuse>
        </material>
        <geometry>
          <mesh>
            <scale>1 1 1</scale>
            <uri>model://vant_4_aerod/meshes/Aileron_R.STL</uri>
          </mesh>
        </geometry>
      </visual>
    </link>
    <joint name='Aileron_R_joint_name' type='revolute'>
      <child>Aileron_R</child>
      <parent>Main_Body</parent>
      <axis>
        <xyz>-0.004942 0.996615 -0.082056</xyz>
        <limit>
          <lower>-1.57</lower>
          <upper>1.57</upper>
          <effort>200</effort>
          <velocity>100</velocity>
        </limit>
        <dynamics>
          <spring_reference>0</spring_reference>
          <spring_stiffness>0</spring_stiffness>
        </dynamics>
        <use_parent_model_frame>1</use_parent_model_frame>
      </axis>
    </joint>
    <link name='Rotor_L'>
      <pose frame=''>0.0780 0.6073 0.1235 0 0 0</pose>
      <inertial>
        <pose frame=''>0 0 0.03 0 -0 0</pose>
        <mass>0.3</mass>
        <inertia>
          <ixx>0.0007</ixx>
          <ixy>3.4E-07</ixy>
          <ixz>1.1E-05</ixz>
          <iyy>0.0007</iyy>
          <iyz>1.5E-05</iyz>
          <izz>0.0002</izz>
        </inertia>
      </inertial>
      <collision name='Rotor_L_collision'>
        <pose frame=''>-0.077968 -0.60727 -0.12348 0 0.015432 0</pose>
        <geometry>
          <mesh>
            <scale>1 1 1</scale>
            <uri>model://vant_4_aerod/meshes/Rotor_L.STL</uri>
          </mesh>
        </geometry>
      </collision>
      <visual name='Rotor_L_visual'>
        <pose frame=''>-0.077968 -0.60727 -0.12348 0 -0.015432 0</pose>
        <material>
          <ambient>0 0 0.75 1</ambient>
          <diffuse>0 0 0.75 1</diffuse>
        </material>
        <geometry>
          <mesh>
            <scale>1 1 1</scale>
            <uri>model://vant_4_aerod/meshes/Rotor_L.STL</uri>
          </mesh>
        </geometry>
      </visual>
    </link>
    <joint name='Rotor_L_joint_name' type='revolute'>
      <child>Rotor_L</child>
      <parent>Main_Body</parent>
      <axis>
        <xyz>-0 1 0</xyz>
        <limit>
          <lower>-1.57</lower>
          <upper>1.57</upper>
          <effort>200</effort>
          <velocity>100</velocity>
        </limit>
        <dynamics>
          <spring_reference>0</spring_reference>
          <spring_stiffness>0</spring_stiffness>
        </dynamics>
        <use_parent_model_frame>1</use_parent_model_frame>
      </axis>
    </joint>
   <link name='Hel_L'>
      <pose frame=''>0.077968 0.60727 0.22 0 -0 0</pose> 
      <inertial>
        <pose frame=''>0 -0 0 0 -0 0</pose>
        <mass>0.0001</mass>
        <inertia>
         <ixx>0.00000001</ixx>
          <ixy>0</ixy>
          <ixz>0.0000000</ixz>
          <iyy>0.00000001</iyy>
          <iyz>0.0000000</iyz>
          <izz>0.00000001</izz>
        </inertia>
      </inertial>
      <collision name='Hel_L_collision'>
        <pose frame=''>-0.077968 -0.60727 -0.22 0 0 0</pose>
        <geometry>
          <mesh>
            <scale>1 1 1</scale>
            <uri>model://vant_4_aerod/meshes/Hel_L.STL</uri>
          </mesh>
        </geometry>
      </collision>
      <visual name='Hel_L_visual'>
        <pose frame=''>-0.08 -0.60727 -0.23 -0 -0 0</pose>
        <material>
          <ambient>0 0 0.75 1</ambient>
          <diffuse>0 0 0.75 1</diffuse>
        </material>
        <geometry>
          <mesh>
            <scale>1 1 1</scale>
            <uri>model://vant_4_aerod/meshes/Hel_L.STL</uri>
          </mesh>
        </geometry>
      </visual>
    </link>
    <joint name='Hel_L_joint_name' type='revolute'>
      <child>Hel_L</child>
      <parent>Rotor_L</parent>
      <axis>
        <xyz>-0.083694 -0.005508 0.996471</xyz>
        <limit>
          <lower>-6.2831</lower>
          <upper>6.2831</upper>
          <effort>200</effort>
          <velocity>100</velocity>
        </limit>
        <dynamics>
          <spring_reference>0</spring_reference>
          <spring_stiffness>0</spring_stiffness>
        </dynamics>
        <use_parent_model_frame>1</use_parent_model_frame>
      </axis>
    </joint> 
    <link name='Rotor_R'>
      <pose frame=''>0.0780 -0.6073 0.1235 0 0 0 </pose>
      <inertial>
        <pose frame=''>0 -0 0.03 0 -0 0</pose>
        <mass>0.3</mass>
        <inertia>
          <ixx>0.0007</ixx>
          <ixy>3.4E-07</ixy>
          <ixz>1.1E-05</ixz>
          <iyy>0.0007</iyy>
          <iyz>1.5E-05</iyz>
          <izz>0.0002</izz>
        </inertia>
      </inertial>
      <collision name='Rotor_R_collision'>
        <pose frame=''>-0.077968 0.60727 -0.12348 -0 -0.015432 0</pose>
        <geometry>
          <mesh>
            <scale>1 1 1</scale>
            <uri>model://vant_4_aerod/meshes/Rotor_R.STL</uri>
          </mesh>
        </geometry>
      </collision>
      <visual name='Rotor_R_visual'>
        <pose frame=''>-0.077968 0.60727 -0.12348 -0 -0.015432 0</pose>
      <material>
          <ambient>0 0 0.75 1</ambient>
          <diffuse>0 0 0.75 1</diffuse>
        </material>
        <geometry>
          <mesh>
            <scale>1 1 1</scale>
            <uri>model://vant_4_aerod/meshes/Rotor_R.STL</uri>
          </mesh>
        </geometry>
      </visual>
    </link>
    <joint name='Rotor_R_joint_name' type='revolute'>
      <child>Rotor_R</child>
      <parent>Main_Body</parent>
      <axis>
        <xyz>-0 1 -0</xyz>
        <limit>
          <lower>-1.57</lower>
          <upper>1.57</upper>
          <effort>200</effort>
          <velocity>100</velocity>
        </limit>
        <dynamics>
          <spring_reference>0</spring_reference>
          <spring_stiffness>0</spring_stiffness>
        </dynamics>
        <use_parent_model_frame>1</use_parent_model_frame>
      </axis>
    </joint>
    <link name='Hel_R'>
      <pose frame=''>0.077968 -0.60727 0.22 0 -0.015432 0</pose>
      <inertial>
        <pose frame=''>0 -0 0 0 -0 0</pose>
        <mass>0.0001</mass>
        <inertia>
          <ixx>0.00000001</ixx>
          <ixy>0</ixy>
          <ixz>0.0000000</ixz>
          <iyy>0.00000001</iyy>
          <iyz>0.0000000</iyz>
          <izz>0.00000001</izz>
        </inertia>
      </inertial>
      <collision name='Hel_R_collision'>
        <pose frame=''>0 0 0 0 -0 0</pose>
        <geometry>
          <mesh>
            <scale>1 1 1</scale>
            <uri>model://vant_4_aerod/meshes/Hel_R.STL</uri>
          </mesh>
        </geometry>
      </collision>
      <visual name='Hel_R_visual'>
        <pose frame=''>-0.077968 0.60727 -0.22 0 -0.015432 0</pose>
        <material>
          <ambient>0 0 0.75 1</ambient>
          <diffuse>0 0 0.75 1</diffuse>
        </material>
        <geometry>
          <mesh>
            <scale>1 1 1</scale>
            <uri>model://vant_4_aerod/meshes/Hel_R.STL</uri>
          </mesh>
        </geometry>
      </visual>
    </link>
    <joint name='Hel_R_joint_name' type='revolute'>
      <child>Hel_R</child>
      <parent>Rotor_R</parent>
      <axis>
        <xyz>-0.015431 0.005508 0.999861</xyz>
       <!-- <limit>
          <lower>-6.2831</lower>
          <upper>6.2831</upper>
          <effort>200</effort>
          <velocity>100</velocity>
        </limit>-->
        <dynamics>
          <spring_reference>0</spring_reference>
          <spring_stiffness>0</spring_stiffness>
        </dynamics>
        <use_parent_model_frame>1</use_parent_model_frame>
      </axis>
    </joint>
    <link name='Rudder_L'>
      <pose frame=''>-0.40846 -0.17214 0.14982 -0.52536 -0.24986 0.006644</pose>
      <inertial>
        <pose frame=''>0 -0 0 0 -0 0</pose>
        <mass>0.0001</mass>
        <inertia>
          <ixx>0.00000001</ixx>
          <ixy>0</ixy>
          <ixz>0.0000000</ixz>
          <iyy>0.00000001</iyy>
          <iyz>0.0000000</iyz>
          <izz>0.00000001</izz>
        </inertia>
      </inertial>
      <collision name='Rudder_L_collision'>
        <pose frame=''>0 0 0 0 -0 0</pose>
        <geometry>
          <mesh>
            <scale>1 1 1</scale>
            <uri>model://vant_4_aerod/meshes/Rudder_L.STL</uri>
          </mesh>
        </geometry>
      </collision>
      <visual name='Rudder_L_visual'>
        <pose frame=''>0 0 0 0 -0 0</pose>
        <material>
          <ambient>0 0 0.75 1</ambient>
          <diffuse>0 0 0.75 1</diffuse>
        </material>
        <geometry>
          <mesh>
            <scale>1 1 1</scale>
            <uri>model://vant_4_aerod/meshes/Rudder_L.STL</uri>
          </mesh>
        </geometry>
      </visual>
    </link>
    <joint name='Rudder_L_joint_name' type='revolute'>
      <child>Rudder_L</child>
      <parent>Main_Body</parent>
      <axis>
        <xyz>0.118261 0.865948 -0.485951</xyz>
        <limit>
          <lower>-1.57</lower>
          <upper>1.57</upper>
          <effort>200</effort>
          <velocity>100</velocity>
        </limit>
        <dynamics>
          <spring_reference>0</spring_reference>
          <spring_stiffness>0</spring_stiffness>
        </dynamics>
        <use_parent_model_frame>1</use_parent_model_frame>
      </axis>
    </joint>
    <link name='Rudder_R'>
      <pose frame=''>-0.40846 0.17214 0.14982 0.50904 -0.075537 0.093637</pose>
      <inertial>
        <pose frame=''>0 -0 0 0 -0 0</pose>
        <mass>0.0001</mass>
        <inertia>
          <ixx>0.00000001</ixx>
          <ixy>0</ixy>
          <ixz>0.0000000</ixz>
          <iyy>0.00000001</iyy>
          <iyz>0.0000000</iyz>
          <izz>0.00000001</izz>
        </inertia>
      </inertial>
      <collision name='Rudder_R_collision'>
        <pose frame=''>0 0 0 0 -0 0</pose>
        <geometry>
          <mesh>
            <scale>1 1 1</scale>
            <uri>model://vant_4_aerod/meshes/Rudder_R.STL</uri>
          </mesh>
        </geometry>
      </collision>
      <visual name='Rudder_R_visual'>
        <pose frame=''>0 0 0 0 -0 0</pose>
        <material>
          <ambient>0 0 0.75 1</ambient>
          <diffuse>0 0 0.75 1</diffuse>
        </material>
        <geometry>
          <mesh>
            <scale>1 1 1</scale>
            <uri>model://vant_4_aerod/meshes/Rudder_R.STL</uri>
          </mesh>
        </geometry>
      </visual>
    </link>
    <joint name='Rudder_R_joint_name' type='revolute'>
      <child>Rudder_R</child>
      <parent>Main_Body</parent>
      <axis>
        <xyz>-0.118262 0.865949 0.48595</xyz>
        <limit>
          <lower>-1.57</lower>
          <upper>1.57</upper>
          <effort>200</effort>
          <velocity>100</velocity>
        </limit>
        <dynamics>
          <spring_reference>0</spring_reference>
          <spring_stiffness>0</spring_stiffness>
        </dynamics>
        <use_parent_model_frame>1</use_parent_model_frame>
      </axis>
    </joint>
    <link name='Fuselage_aerodcenter'>
      <pose frame=''>0 0 0 0 0 0</pose>
      <inertial>
        <pose frame=''>0.0512 0 0.10 0 -0 0</pose>
        <mass>0.1</mass>
        <inertia>
        	<ixx>0.0000001</ixx>
        	<ixy>0</ixy>
        	<ixz>0</ixz>
        	<iyy>0.0000001</iyy>
        	<iyz>0</iyz>
        	<izz>0.0000001</izz>
       	</inertia>
      </inertial>
    </link>
    <link name='WingR_aerodcenter'>
      <pose frame=''>0 0 0 0 0 0</pose>
      <inertial>
        <pose>0.0512 -0.31 0.10 -0.0873 0 0</pose>
        <mass>0.1</mass>
        <inertia>
        	<ixx>0.0000001</ixx>
        	<ixy>0</ixy>
        	<ixz>0</ixz>
        	<iyy>0.0000001</iyy>
        	<iyz>0</iyz>
        	<izz>0.0000001</izz>
       	</inertia>
      </inertial>
    </link>
         <link name="WingL_aerodcenter">
            <pose>0 0 0 0 0 0</pose>
            <inertial>
                <mass>0.1</mass>
                <pose>0.0512 0.31 0.10 0.0873 0 0</pose>
                <inertia>
                    <ixx>0.0000001</ixx>
                    <ixy>0</ixy>
                    <ixz>0</ixz>
                    <iyy>0.0000001</iyy>
                    <iyz>0</iyz>
                    <izz>0.0000001</izz>
                </inertia>
            </inertial>
        </link>
         <link name="RudR_aerodcenter">
            <pose>0 0 0 0 0 0</pose>
            <inertial>
                <mass>0.1</mass>
                <pose>-0.3967 -0.168 0.148 -0.5061 0 0</pose>
                <inertia>
                    <ixx>0.0000001</ixx>
                    <ixy>0</ixy>
                    <ixz>0</ixz>
                    <iyy>0.0000001</iyy>
                    <iyz>0</iyz>
                    <izz>0.0000001</izz>
                </inertia>
            </inertial>
        </link>
         <link name="RudL_aerodcenter">
            <pose>0 0 0 0 0 0</pose>
            <inertial>
                <mass>0.1</mass>
                <pose>-0.3967 0.168 0.148 0.5061 0 0</pose>
                <inertia>
                    <ixx>0.0000001</ixx>
                    <ixy>0</ixy>
                    <ixz>0</ixz>
                    <iyy>0.0000001</iyy>
                    <iyz>0</iyz>
                    <izz>0.0000001</izz>
                </inertia>
            </inertial>
        </link>
  
<!--<plugin name="empuxo"
filename="libgazebo_ros_brushless_plugin.so">
            <topic_FR>Thrustdir</topic_FR>
            <LinkDir>Hel_R</LinkDir>
            <topic_FL>Thrustesq</topic_FL>
            <LinkEsq>Hel_L</LinkEsq>
            <DragCte>0.0001</DragCte>     
     </plugin> -->																				
   <plugin name="VetorEstados"
filename="libgazebo_ros_AllData_plugin.so">
            <NameOfTopic>Estados</NameOfTopic>
            <NameOfJointR>Rotor_R_joint_name</NameOfJointR>
            <NameOfJointL>Rotor_L_joint_name</NameOfJointL>
            <bodyName>Main_Body</bodyName>
     </plugin>    
     <plugin name="RotorRplugin"
filename="libgazebo_ros_servo_motor_plugin.so">
            <NameOfJoint>Rotor_R_joint_name</NameOfJoint>   
            <TopicPublisher>RotorRpub</TopicPublisher>
            <TopicSubscriber>RefRotorR</TopicSubscriber>
            <Modo>Torque</Modo>
            <Saturation>1</Saturation>
     </plugin>
      <plugin name="RotorLplugin"
filename="libgazebo_ros_servo_motor_plugin.so">
            <NameOfJoint>Rotor_L_joint_name</NameOfJoint>
            <TopicPublisher>RotorLpub</TopicPublisher>
            <TopicSubscriber>RefRotorL</TopicSubscriber>
            <Modo>Torque</Modo>
            <Saturation>1</Saturation>
  </plugin>
	<plugin name="AileronRplugin"
filename="libgazebo_ros_servo_motor_plugin.so">
            <NameOfJoint>Aileron_R_joint_name</NameOfJoint>
            <TopicPublisher>AileronRpub</TopicPublisher>
            <TopicSubscriber>RefAileronR</TopicSubscriber>
            <Modo>Position</Modo> 
            <Saturation>1</Saturation>          
  </plugin>
   	<plugin name="AileronLplugin"
filename="libgazebo_ros_servo_motor_plugin.so">
            <NameOfJoint>Aileron_L_joint_name</NameOfJoint>
            <TopicPublisher>AileronLpub</TopicPublisher>
            <TopicSubscriber>RefAileronL</TopicSubscriber>
            <Modo>Position</Modo> 
            <Saturation>1</Saturation>          
  </plugin>
  	<plugin name="RudderRplugin"
filename="libgazebo_ros_servo_motor_plugin.so">
            <NameOfJoint>Rudder_R_joint_name</NameOfJoint>
            <TopicPublisher>RudderRpub</TopicPublisher>
            <TopicSubscriber>RefRudderR</TopicSubscriber>
            <Modo>Position</Modo> 
            <Saturation>1</Saturation>         
  </plugin>
   	<plugin name="RudderLplugin"
filename="libgazebo_ros_servo_motor_plugin.so">
            <NameOfJoint>Rudder_L_joint_name</NameOfJoint>
            <TopicPublisher>RudderLpub</TopicPublisher>
            <TopicSubscriber>RefRudderL</TopicSubscriber>
            <Modo>Position</Modo>
            <Saturation>1</Saturation>
  	</plugin> 
   <plugin name="empuxo" filename="libgazebo_ros_Aerodinamica4dot0_plugin.so">
            <MainBody> Main_Body </MainBody>
            <NameOfNode> Estados </NameOfNode>				
            <topic_Fr> ThrustR </topic_Fr> 
            <LinkFr> Rotor_R </LinkFr>
            <topic_Fl> ThrustL </topic_Fl>		<!--ThrustL-->
            <LinkFl> Rotor_L </LinkFl>				
	    <topic_AileronR> RefAileronR </topic_AileronR>
	    <LinkAileronR>Aileron_R</LinkAileronR>
	    <CentroAerod_F> Fuselage_aerodcenter </CentroAerod_F>		
            <CentroAerod_Wr> WingR_aerodcenter </CentroAerod_Wr>
            <topic_AileronL> RefAileronL </topic_AileronL>
            <LinkAileronL>Aileron_L</LinkAileronL>	
            <CentroAerod_Wl> WingL_aerodcenter </CentroAerod_Wl>
       <!--    <JointAileronR>Aileron_R_joint_name</JointAileronR>	-->
            <CentroAerod_RudR> RudR_aerodcenter </CentroAerod_RudR>
            <CentroAerod_RudL> RudL_aerodcenter </CentroAerod_RudL>
           <topic_RudderR> RefRudderR </topic_RudderR>
            <topic_RudderL> RefRudderL </topic_RudderL>	
            <LinkRudderR>Rudder_R</LinkRudderR>
            <LinkRudderL>Rudder_L</LinkRudderL>				
            <!--    <JointFr>  Hel_L_joint_name  </JointFr>		
                  <JointFl>  Hel_R_joint_name  </JointFl> 	
              <topic_Wl> Wl_topic </topic_Wl>	-->			
        </plugin>	
  </model>
</sdf>
