<?xml version="1.0" encoding="UTF-8"?>
<!--
This file is part of the ProVANT simulator project.
Licensed under the terms of the MIT open source license. More details at
https: //github.com/Guiraffo/ProVANT-Simulator/blob/master/LICENSE.md
-->
<!-- Note: This file is only contained for example purposes. Please
use to URDF version of this model. -->
<sdf version='1.7'>
  <model name='robotic_manipulator'>
    <joint name='base_fixed' type='fixed'>
      <pose relative_to='__model__'>0 0 0 0 -0 0</pose>
      <parent>world</parent>
      <child>base_link</child>
    </joint>
    <link name='base_link'>
      <pose relative_to='base_fixed'>0 0 0 0 -0 0</pose>
      <inertial>
        <pose>-0.001633 -0 0.041253 0 -0 0</pose>
        <mass>5.9348</mass>
        <inertia>
          <ixx>0.069314</ixx>
          <ixy>-7.9117e-09</ixy>
          <ixz>0.00044735</ixz>
          <iyy>0.069119</iyy>
          <iyz>3.8918e-08</iyz>
          <izz>0.12076</izz>
        </inertia>
      </inertial>
      <collision name='base_link_collision'>
        <pose>0 0 0 0 -0 0</pose>
        <geometry>
          <mesh>
            <scale>1 1 1</scale>
            <uri>model://arm_model/meshes/base_link.STL</uri>
          </mesh>
        </geometry>
        <surface>
          <contact>
            <ode />
          </contact>
          <friction>
            <ode />
          </friction>
        </surface>
      </collision>
      <visual name='base_link_visual'>
        <pose>0 0 0 0 -0 0</pose>
        <geometry>
          <mesh>
            <scale>1 1 1</scale>
            <uri>model://arm_model/meshes/base_link.STL</uri>
          </mesh>
        </geometry>
      </visual>
    </link>
    <joint name='base_link1' type='revolute'>
      <pose relative_to='base_link'>-0.055 0 0.17 -1.5708 -1.3513 3.14159</pose>
      <parent>base_link</parent>
      <child>link1</child>
      <axis>
        <xyz>0 0 1</xyz>
        <limit>
          <lower>-1.5708</lower>
          <upper>1.5708</upper>
          <effort>100</effort>
          <velocity>20</velocity>
        </limit>
        <dynamics>
          <spring_reference>0</spring_reference>
          <spring_stiffness>0</spring_stiffness>
        </dynamics>
      </axis>
      <physics>
        <provide_feedback>1</provide_feedback>
        <ode>
          <limit>
            <cfm>0</cfm>
            <erp>0.2</erp>
          </limit>
          <provide_feedback>1</provide_feedback>
        </ode>
      </physics>
    </joint>
    <link name='link1'>
      <pose relative_to='base_link1'>0 0 0 0 -0 0</pose>
      <inertial>
        <pose>0.28436 0 0.000931 0 -0 0</pose>
        <mass>1.8828</mass>
        <inertia>
          <ixx>0.0051206</ixx>
          <ixy>1.917e-08</ixy>
          <ixz>1.3958e-08</ixz>
          <iyy>0.047785</iyy>
          <iyz>-1.0301e-09</iyz>
          <izz>0.04779</izz>
        </inertia>
      </inertial>
      <collision name='link1_collision'>
        <pose>0 0 0 0 -0 0</pose>
        <geometry>
          <mesh>
            <scale>1 1 1</scale>
            <uri>model://arm_model/meshes/link1.STL</uri>
          </mesh>
        </geometry>
      </collision>
      <visual name='link1_visual'>
        <pose>0 0 0 0 -0 0</pose>
        <geometry>
          <mesh>
            <scale>1 1 1</scale>
            <uri>model://arm_model/meshes/link1.STL</uri>
          </mesh>
        </geometry>
      </visual>
    </link>
    <joint name='link1_link2' type='revolute'>
      <pose relative_to='link1'>0.554 0 0.1265 0 0 -0.99459</pose>
      <parent>link1</parent>
      <child>link2</child>
      <axis>
        <xyz>0 0 1</xyz>
        <limit>
          <lower>-1.5708</lower>
          <upper>1.5708</upper>
          <effort>100</effort>
          <velocity>20</velocity>
        </limit>
        <dynamics>
          <spring_reference>0</spring_reference>
          <spring_stiffness>0</spring_stiffness>
        </dynamics>
      </axis>
    </joint>
    <link name='link2'>
      <pose relative_to='link1_link2'>0 0 0 0 -0 0</pose>
      <inertial>
        <pose>0.51681 0.06743 -0.021574 0 -0 0</pose>
        <mass>4.3972</mass>
        <inertia>
          <ixx>0.0091558</ixx>
          <ixy>0.00017039</ixy>
          <ixz>-9.1435e-05</ixz>
          <iyy>0.056149</iyy>
          <iyz>-9.3814e-06</iyz>
          <izz>0.056624</izz>
        </inertia>
      </inertial>
      <collision name='link2_collision'>
        <pose>0 0 0 0 -0 0</pose>
        <geometry>
          <mesh>
            <scale>1 1 1</scale>
            <uri>model://arm_model/meshes/link2.STL</uri>
          </mesh>
        </geometry>
      </collision>
      <visual name='link2_visual'>
        <pose>0 0 0 0 -0 0</pose>
        <geometry>
          <mesh>
            <scale>1 1 1</scale>
            <uri>model://arm_model/meshes/link2.STL</uri>
          </mesh>
        </geometry>
      </visual>
    </link>
    <plugin name='actuator' filename='libgazebo_ros_ArmForces.so'>
      <joint1>base_link1</joint1>
      <joint2>link1_link2</joint2>
      <joint1_torque_topic>joint1_torque</joint1_torque_topic>
      <joint2_torque_topic>joint2_torque</joint2_torque_topic>
    </plugin>
    <static>0</static>
  </model>
</sdf>