<?xml version="1.0" encoding="utf-8"?>
<!--
This file is part of the ProVANT simulator project.
Licensed under the terms of the MIT open source license. More details at
https: //github.com/Guiraffo/ProVANT-Simulator/blob/master/LICENSE.md
-->
<robot name="robotic_manipulator">
  <!-- This link was created so that the manipulator is fixed to the ground plane. -->
  <link name="world" />
  <link name="base_link">
    <inertial>
      <origin xyz="-0.001633 -3.7247E-08 0.041253" rpy="0 0 0" />
      <mass value="5.9348" />
      <inertia ixx="0.071104" ixy="7.69715E-09" ixz="-0.001189108" iyy="0.071216" iyz="-3.84003E-08" izz="0.12106728" />
    </inertial>
    <visual>
      <origin xyz="0 0 0" rpy="0 0 0" />
      <geometry>
        <mesh filename="package://arm_model/meshes/base_link.STL" />
      </geometry>
      <material name="">
        <color rgba="0.79216 0.81961 0.93333 1" />
      </material>
    </visual>
    <collision>
      <origin xyz="0 0 0" rpy="0 0 0" />
      <geometry>
        <mesh filename="package://arm_model/meshes/base_link.STL" />
      </geometry>
    </collision>
  </link>
  <joint name="base_fixed" type="fixed">
    <parent link="world" />
    <child link="base_link" />
  </joint>
  <link name="link1">
    <inertial>
      <origin xyz="0.28436 6.6154E-08 0.00093129" rpy="0 0 0" />
      <mass value="1.8828" />
      <inertia ixx="0.0051206" ixy="-1.97882E-08" ixz="0.000472772" iyy="0.050395" iyz="9.14107E-10" izz="0.050310566" />
    </inertial>
    <visual>
      <origin xyz="0 0 0" rpy="0 0 0" />
      <geometry>
        <mesh filename="package://arm_model/meshes/link1.STL" />
      </geometry>
      <material name="">
        <color rgba="0.79216 0.81961 0.93333 1" />
      </material>
    </visual>
    <collision>
      <origin xyz="0 0 0" rpy="0 0 0" />
      <geometry>
        <mesh filename="package://arm_model/meshes/link1.STL" />
      </geometry>
    </collision>
  </link>
  <joint name="base_link1" type="revolute">
    <origin xyz="-0.055 0 0.17" rpy="-1.5708 -1.3513 -3.1416" />
    <parent link="base_link" />
    <child link="link1" />
    <axis xyz="0 0 1" />
    <limit lower="-1.57079633" upper="1.57079633" effort="100" velocity="20" />
  </joint>
  <link name="link2">
    <inertial>
      <!-- Values considering that the link2 doesn't have the gripper attached to it. -->
      <origin xyz="0.28975704 0 -0.0235" rpy="0 0 0" />
      <mass value="1.9547537" />
      <inertia ixx="0.005261" ixy="1.72821E-08" ixz="-1.41385E-08" iyy="0.055753" iyz="-1.0301E-09" izz="0.055628321" />
    </inertial>
    <visual>
      <origin xyz="0 0 0" rpy="0 0 0" />
      <geometry>
        <mesh filename="package://arm_model/meshes/link2.STL" />
      </geometry>
      <material name="">
        <color rgba="0.79216 0.81961 0.93333 1" />
      </material>
    </visual>
    <collision>
      <origin xyz="0 0 0" rpy="0 0 0" />
      <geometry>
        <mesh filename="package://arm_model/meshes/link2.STL" />
      </geometry>
    </collision>
  </link>
  <joint name="link1_link2" type="revolute">
    <origin xyz="0.554 0 0.1265" rpy="0 0 -0.99459" />
    <parent link="link1" />
    <child link="link2" />
    <axis xyz="0 0 1" />
    <limit lower="-1.57079633" upper="1.57079633" effort="100" velocity="20" />
  </joint>

  <!-- Additional configurations for the model -->
  <gazebo>
    <plugin name="actuator" filename="libgazebo_ros_ArmForces.so">
      <joint1>base_link1</joint1>
      <joint2>link1_link2</joint2>
      <joint1_torque_topic>joint1_torque</joint1_torque_topic>
      <joint2_torque_topic>joint2_torque</joint2_torque_topic>
    </plugin>
  </gazebo>

  <!-- Additional configuration for the links -->
  <gazebo reference="base_link">
    <static>false</static>
  </gazebo>

  <gazebo reference="link1"></gazebo>

  <gazebo reference="link2"></gazebo>

  <!-- Additional configuration for the joints -->
  <gazebo reference="base_link1">
    <provideFeedback>true</provideFeedback>
  </gazebo>

  <gazebo refernce="link1_link2">
    <provideFeedback>true</provideFeedback>
  </gazebo>

</robot>