<?xml version="1.0" encoding="UTF-8"?>
<!--
This file is part of the ProVANT simulator project.
Licensed under the terms of the MIT open source license. More details at
https://github.com/Guiraffo/ProVANT-Simulator/blob/master/LICENSE.md
-->
<sdf version='1.6'>
  <model name='provant_alpha_quadrotor'>
    <link name='base_link'>
      <pose frame=''>0 0 0 0 -0 0</pose>
      <inertial>
        <pose frame=''>-0 -0 0.17359 0 -0 0</pose>
        <mass>2.34623</mass>
        <inertia>
          <ixx>0.0138948</ixx>
          <ixy>-7.60561e-17</ixy>
          <ixz>1.99836e-17</ixz>
          <iyy>0.0138948</iyy>
          <iyz>4.90255e-17</iyz>
          <izz>0.0234571</izz>
        </inertia>
      </inertial>
      <collision name='base_link_collision'>
        <pose frame=''>0 0 0 0 -0 0</pose>
        <geometry>
          <mesh>
            <scale>1 1 1</scale>
            <uri>model://provant_alpha_quadrotor/meshes/base_link.STL</uri>
          </mesh>
        </geometry>
        <surface>
          <contact>
            <ode />
          </contact>
          <friction>
            <ode />
          </friction>
        </surface>
        base_link
      </collision>
      <collision name='base_link_fixed_joint_lump__legs_collision_1'>
        <pose frame=''>0 0 0 0 -0 0</pose>
        <geometry>
          <mesh>
            <scale>1 1 1</scale>
            <uri>model://provant_alpha_quadrotor/meshes/legs.STL</uri>
          </mesh>
        </geometry>
        <surface>
          <contact>
            <ode />
          </contact>
          <friction>
            <ode />
          </friction>
        </surface>
      </collision>
      <visual name='base_link_visual'>
        <pose frame=''>0 0 0 0 -0 0</pose>
        <geometry>
          <mesh>
            <scale>1 1 1</scale>
            <uri>model://provant_alpha_quadrotor/meshes/base_link.STL</uri>
          </mesh>
        </geometry>
        <material>
          <script>
            <name>Gazebo/Red</name>
            <uri>file://media/materials/scripts/gazebo.material</uri>
          </script>
        </material>
      </visual>
      <visual name='base_link_fixed_joint_lump__legs_visual_1'>
        <pose frame=''>0 0 0 0 -0 0</pose>
        <geometry>
          <mesh>
            <scale>1 1 1</scale>
            <uri>model://provant_alpha_quadrotor/meshes/legs.STL</uri>
          </mesh>
        </geometry>
        <material>
          <script>
            <name>Gazebo/Black</name>
            <uri>file://media/materials/scripts/gazebo.material</uri>
          </script>
        </material>
      </visual>
      <velocity_decay />
      <gravity>1</gravity>
      <velocity_decay />
    </link>
    <link name='prop1'>
      <pose frame=''>0.3 0 0.2005 0 -0 0</pose>
      <inertial>
        <pose frame=''>0 -0 0.022024 0 -0 0</pose>
        <mass>0.0900308</mass>
        <inertia>
          <ixx>4.47942e-05</ixx>
          <ixy>2.0665e-05</ixy>
          <ixz>5.03946e-20</ixz>
          <iyy>2.52109e-05</iyy>
          <iyz>-7.11701e-20</iyz>
          <izz>5.78163e-05</izz>
        </inertia>
      </inertial>
      <collision name='prop1_collision'>
        <pose frame=''>0 0 0 0 -0 0</pose>
        <geometry>
          <mesh>
            <scale>1 1 1</scale>
            <uri>model://provant_alpha_quadrotor/meshes/prop1.STL</uri>
          </mesh>
        </geometry>
        <surface>
          <contact>
            <ode />
          </contact>
          <friction>
            <ode />
          </friction>
        </surface>
      </collision>
      <visual name='prop1_visual'>
        <pose frame=''>0 0 0 0 -0 0</pose>
        <geometry>
          <mesh>
            <scale>1 1 1</scale>
            <uri>model://provant_alpha_quadrotor/meshes/prop1.STL</uri>
          </mesh>
        </geometry>
        <material>
          <script>
            <name>Gazebo/White</name>
            <uri>file://media/materials/scripts/gazebo.material</uri>
          </script>
        </material>
      </visual>
      <gravity>1</gravity>
      <velocity_decay />
    </link>
    <joint name='f1' type='revolute'>
      <child>prop1</child>
      <parent>base_link</parent>
      <axis>
        <xyz>0 0 1</xyz>
        <limit>
          <lower>-1e+16</lower>
          <upper>1e+16</upper>
        </limit>
        <dynamics>
          <spring_reference>0</spring_reference>
          <spring_stiffness>0</spring_stiffness>
        </dynamics>
        <use_parent_model_frame>1</use_parent_model_frame>
      </axis>
    </joint>
    <link name='prop2'>
      <pose frame=''>0 0.3 0.2005 0 -0 0</pose>
      <inertial>
        <pose frame=''>0 0 0.022024 0 -0 0</pose>
        <mass>0.0900308</mass>
        <inertia>
          <ixx>4.47942e-05</ixx>
          <ixy>2.0665e-05</ixy>
          <ixz>-6.3683e-21</ixz>
          <iyy>2.52109e-05</iyy>
          <iyz>-3.19399e-21</iyz>
          <izz>5.78163e-05</izz>
        </inertia>
      </inertial>
      <collision name='prop2_collision'>
        <pose frame=''>0 0 0 0 -0 0</pose>
        <geometry>
          <mesh>
            <scale>1 1 1</scale>
            <uri>model://provant_alpha_quadrotor/meshes/prop2.STL</uri>
          </mesh>
        </geometry>
        <surface>
          <contact>
            <ode />
          </contact>
          <friction>
            <ode />
          </friction>
        </surface>
      </collision>
      <visual name='prop2_visual'>
        <pose frame=''>0 0 0 0 -0 0</pose>
        <geometry>
          <mesh>
            <scale>1 1 1</scale>
            <uri>model://provant_alpha_quadrotor/meshes/prop2.STL</uri>
          </mesh>
        </geometry>
        <material>
          <script>
            <name>Gazebo/White</name>
            <uri>file://media/materials/scripts/gazebo.material</uri>
          </script>
        </material>
      </visual>
      <gravity>1</gravity>
      <velocity_decay />
    </link>
    <joint name='f2' type='revolute'>
      <child>prop2</child>
      <parent>base_link</parent>
      <axis>
        <xyz>0 0 1</xyz>
        <limit>
          <lower>-1e+16</lower>
          <upper>1e+16</upper>
        </limit>
        <dynamics>
          <spring_reference>0</spring_reference>
          <spring_stiffness>0</spring_stiffness>
        </dynamics>
        <use_parent_model_frame>1</use_parent_model_frame>
      </axis>
    </joint>
    <link name='prop3'>
      <pose frame=''>-0.3 0 0.2005 0 -0 0</pose>
      <inertial>
        <pose frame=''>-0 0 0.022024 0 -0 0</pose>
        <mass>0.0900308</mass>
        <inertia>
          <ixx>4.47942e-05</ixx>
          <ixy>2.0665e-05</ixy>
          <ixz>-6.52157e-21</ixz>
          <iyy>2.52109e-05</iyy>
          <iyz>-4.87208e-21</iyz>
          <izz>5.78163e-05</izz>
        </inertia>
      </inertial>
      <collision name='prop3_collision'>
        <pose frame=''>0 0 0 0 -0 0</pose>
        <geometry>
          <mesh>
            <scale>1 1 1</scale>
            <uri>model://provant_alpha_quadrotor/meshes/prop3.STL</uri>
          </mesh>
        </geometry>
        <surface>
          <contact>
            <ode />
          </contact>
          <friction>
            <ode />
          </friction>
        </surface>
      </collision>
      <visual name='prop3_visual'>
        <pose frame=''>0 0 0 0 -0 0</pose>
        <geometry>
          <mesh>
            <scale>1 1 1</scale>
            <uri>model://provant_alpha_quadrotor/meshes/prop3.STL</uri>
          </mesh>
        </geometry>
        <material>
          <script>
            <name>Gazebo/White</name>
            <uri>file://media/materials/scripts/gazebo.material</uri>
          </script>
        </material>
      </visual>
      <gravity>1</gravity>
      <velocity_decay />
    </link>
    <joint name='f3' type='revolute'>
      <child>prop3</child>
      <parent>base_link</parent>
      <axis>
        <xyz>0 0 1</xyz>
        <limit>
          <lower>-1e+16</lower>
          <upper>1e+16</upper>
        </limit>
        <dynamics>
          <spring_reference>0</spring_reference>
          <spring_stiffness>0</spring_stiffness>
        </dynamics>
        <use_parent_model_frame>1</use_parent_model_frame>
      </axis>
    </joint>
    <link name='prop4'>
      <pose frame=''>0 -0.3 0.2005 0 -0 0</pose>
      <inertial>
        <pose frame=''>0 0 0.021024 0 -0 0</pose>
        <mass>0.0900308</mass>
        <inertia>
          <ixx>2.52109e-05</ixx>
          <ixy>-2.0665e-05</ixy>
          <ixz>-9.97942e-21</ixz>
          <iyy>4.47942e-05</iyy>
          <iyz>-2.16492e-21</iyz>
          <izz>5.78163e-05</izz>
        </inertia>
      </inertial>
      <collision name='prop4_collision'>
        <pose frame=''>0 0 0 0 -0 0</pose>
        <geometry>
          <mesh>
            <scale>1 1 1</scale>
            <uri>model://provant_alpha_quadrotor/meshes/prop4.STL</uri>
          </mesh>
        </geometry>
        <surface>
          <contact>
            <ode />
          </contact>
          <friction>
            <ode />
          </friction>
        </surface>
      </collision>
      <visual name='prop4_visual'>
        <pose frame=''>0 0 0 0 -0 0</pose>
        <geometry>
          <mesh>
            <scale>1 1 1</scale>
            <uri>model://provant_alpha_quadrotor/meshes/prop4.STL</uri>
          </mesh>
        </geometry>
        <material>
          <script>
            <name>Gazebo/White</name>
            <uri>file://media/materials/scripts/gazebo.material</uri>
          </script>
        </material>
      </visual>
      <gravity>1</gravity>
      <velocity_decay />
    </link>
    <joint name='f4' type='revolute'>
      <child>prop4</child>
      <parent>base_link</parent>
      <axis>
        <xyz>0 0 1</xyz>
        <limit>
          <lower>-1e+16</lower>
          <upper>1e+16</upper>
        </limit>
        <dynamics>
          <spring_reference>0</spring_reference>
          <spring_stiffness>0</spring_stiffness>
        </dynamics>
        <use_parent_model_frame>1</use_parent_model_frame>
      </axis>
    </joint>
    <static>0</static>
    <plugin name="VetorEstados" filename="libgazebo_ros_QuadData.so">
      <NameOfTopic>Estados</NameOfTopic>
      <bodyName>base_link</bodyName>
    </plugin>
    <plugin name="empuxo" filename="libgazebo_ros_QuadForces.so">
      <topic_F1>Empuxoh1</topic_F1>
      <topic_F2>Empuxoh2</topic_F2>
      <topic_F3>Empuxoh3</topic_F3>
      <topic_F4>Empuxoh4</topic_F4>
      <body>base_link</body>
      <DragCte>0.0179</DragCte>
      <alpha>0.087</alpha>
      <length>0.3</length>
      <saturate>false</saturate>
    </plugin>
    <plugin name="vs_propeller_1_3" filename="libgazebo_ros_VisualPropellers.so">
      <Propeller1>f1</Propeller1>
      <Propeller2>f3</Propeller2>
      <Propellers_Velocity>30</Propellers_Velocity>
    </plugin>
    <plugin name="vs_propeller_2_4" filename="libgazebo_ros_VisualPropellers.so">
      <Propeller1>f2</Propeller1>
      <Propeller2>f4</Propeller2>
      <Propellers_Velocity>-30</Propellers_Velocity>
    </plugin>
  </model>
</sdf>