<?xml version="1.0" encoding="utf-8"?>
<!--
This file is part of the ProVANT simulator project.
Licensed under the terms of the MIT open source license. More details at
https://github.com/Guiraffo/ProVANT-Simulator/blob/master/LICENSE.md
-->
<robot
  name="provant_alpha_quadrotor">
    <!-- Use with <material>Gazebo/Black</material>-->
  <material name="black">
    <color rgba="0.0 0.0 0.0 1.0"/>
  </material>

  <material name="blue">
    <color rgba="0.0 0.0 0.8 1.0"/>
  </material>

  <material name="green">
    <color rgba="0.0 0.8 0.0 1.0"/>
  </material>

  <material name="grey">
    <color rgba="0.2 0.2 0.2 1.0"/>
  </material>
  
  <!-- Use with <material>Gazebo/Orange</material>-->
  <material name="orange">
    <color rgba="1 0.42353 0.03922 1.0"/>
  </material>

  <material name="brown">
    <color rgba="1.0 0.81177 0.76471 1.0"/>
  </material>

  <!-- Use with <material>Gazebo/Red</material>-->
  <material name="red">
    <color rgba="0.8 0.0 0.0 1.0"/>
  </material>

  <material name="white">
    <color rgba="1.0 1.0 1.0 1.0"/>
  </material>

  <!-- Necessary for Rviz visualization of the model -->
  <link
    name="base_link">
    <inertial>
      <origin
        xyz="-6.66133814775094E-16 -1.55431223447522E-15 0.180998857571939"
        rpy="0 0 0" />
      <mass
        value="2.2" />
      <inertia
        ixx="0.0117197858769209"
        ixy="-7.63245755057274E-17"
        ixz="1.16636444461938E-18"
        iyy="0.0117197858769209"
        iyz="5.58752635680239E-18"
        izz="0.0234029287921774" />
    </inertial>
    <visual>
      <origin
        xyz="0 0 0"
        rpy="0 0 0" />
      <geometry>
        <mesh
          filename="model://provant_alpha_quadrotor/meshes/base_link.STL" />
      </geometry>
      <material
        name="">
        <color
          rgba="1 1 1 1" />
      </material>
    </visual>
    <collision>
      <origin
        xyz="0 0 0"
        rpy="0 0 0" />
      <geometry>
        <mesh
          filename="model://provant_alpha_quadrotor/meshes/base_link.STL" />
      </geometry>
    </collision>
  </link>
  <link
    name="legs">
    <inertial>
      <origin
        xyz="5.55111512312578E-16 1.11022302462516E-15 0.0621262276194157"
        rpy="0 0 0" />
      <mass
        value="0.14623345246629" />
      <inertia
        ixx="0.000237434770940027"
        ixy="2.68509444279613E-19"
        ixz="-1.08873598996886E-18"
        iyy="0.000237434770940027"
        iyz="6.77626357804862E-21"
        izz="5.41386422243988E-05" />
    </inertial>
    <visual>
      <origin
        xyz="0 0 0"
        rpy="0 0 0" />
      <geometry>
        <mesh
          filename="model://provant_alpha_quadrotor/meshes/legs.STL" />
      </geometry>
      <material
        name="">
        <color
          rgba="1 1 1 1" />
      </material>
    </visual>
    <collision>
      <origin
        xyz="0 0 0"
        rpy="0 0 0" />
      <geometry>
        <mesh
          filename="model://provant_alpha_quadrotor/meshes/legs.STL" />
      </geometry>
    </collision>
  </link>
  <joint
    name="joint1"
    type="fixed">
    <origin
      xyz="0 0 0"
      rpy="0 0 0" />
    <parent
      link="base_link" />
    <child
      link="legs" />
    <axis
      xyz="0 0 0" />
  </joint>
  <link
    name="prop1">
    <inertial>
      <origin
        xyz="0 -1.66533453693773E-16 0.0220243882624624"
        rpy="0 0 0" />
      <mass
        value="0.0900308275627489" />
      <inertia
        ixx="4.47942174809247E-05"
        ixy="2.06649562901672E-05"
        ixz="5.03946016627054E-20"
        iyy="2.521089655902E-05"
        iyz="-7.11700751667277E-20"
        izz="5.78162740600789E-05" />
    </inertial>
    <visual>
      <origin
        xyz="0 0 0"
        rpy="0 0 0" />
      <geometry>
        <mesh
          filename="model://provant_alpha_quadrotor/meshes/prop1.STL" />
      </geometry>
      <material
        name="">
        <color
          rgba="0.752941176470588 0.752941176470588 0.752941176470588 1" />
      </material>
    </visual>
    <collision>
      <origin
        xyz="0 0 0"
        rpy="0 0 0" />
      <geometry>
        <mesh
          filename="model://provant_alpha_quadrotor/meshes/prop1.STL" />
      </geometry>
    </collision>
  </link>
  <joint
    name="f1"
    type="continuous">
    <origin
      xyz="0.3 0 0.2005"
      rpy="0 0 0" />
    <parent
      link="base_link" />
    <child
      link="prop1" />
    <axis
      xyz="0 0 -1" />
    <limit
      effort="0"
      velocity="0" />
  </joint>
  <link
    name="prop2">
    <inertial>
      <origin
        xyz="2.22044604925031E-16 0 0.0220243882624623"
        rpy="0 0 0" />
      <mass
        value="0.090030827562749" />
      <inertia
        ixx="4.4794217480925E-05"
        ixy="2.06649562901671E-05"
        ixz="-6.3683033054006E-21"
        iyy="2.52108965590198E-05"
        iyz="-3.19398545463806E-21"
        izz="5.7816274060079E-05" />
    </inertial>
    <visual>
      <origin
        xyz="0 0 0"
        rpy="0 0 0" />
      <geometry>
        <mesh
          filename="model://provant_alpha_quadrotor/meshes/prop2.STL" />
      </geometry>
      <material
        name="">
        <color
          rgba="0.752941176470588 0.752941176470588 0.752941176470588 1" />
      </material>
    </visual>
    <collision>
      <origin
        xyz="0 0 0"
        rpy="0 0 0" />
      <geometry>
        <mesh
          filename="model://provant_alpha_quadrotor/meshes/prop2.STL" />
      </geometry>
    </collision>
  </link>
  <joint
    name="f2"
    type="continuous">
    <origin
      xyz="0 0.3 0.2005"
      rpy="0 0 0" />
    <parent
      link="base_link" />
    <child
      link="prop2" />
    <axis
      xyz="0 0 -1" />
    <limit
      effort="0"
      velocity="0" />
  </joint>
  <link
    name="prop3">
    <inertial>
      <origin
        xyz="-1.11022302462516E-16 0 0.0220243882624621"
        rpy="0 0 0" />
      <mass
        value="0.0900308275627489" />
      <inertia
        ixx="4.47942174809249E-05"
        ixy="2.06649562901671E-05"
        ixz="-6.5215728108858E-21"
        iyy="2.52108965590197E-05"
        iyz="-4.87207536330794E-21"
        izz="5.78162740600789E-05" />
    </inertial>
    <visual>
      <origin
        xyz="0 0 0"
        rpy="0 0 0" />
      <geometry>
        <mesh
          filename="model://provant_alpha_quadrotor/meshes/prop3.STL" />
      </geometry>
      <material
        name="">
        <color
          rgba="0.752941176470588 0.752941176470588 0.752941176470588 1" />
      </material>
    </visual>
    <collision>
      <origin
        xyz="0 0 0"
        rpy="0 0 0" />
      <geometry>
        <mesh
          filename="model://provant_alpha_quadrotor/meshes/prop3.STL" />
      </geometry>
    </collision>
  </link>
  <joint
    name="f3"
    type="continuous">
    <origin
      xyz="-0.3 0 0.2005"
      rpy="0 0 0" />
    <parent
      link="base_link" />
    <child
      link="prop3" />
    <axis
      xyz="0 0 -1" />
    <limit
      effort="0"
      velocity="0" />
  </joint>
  <link
    name="prop4">
    <inertial>
      <origin
        xyz="2.22044604925031E-16 1.38777878078145E-17 0.0210243882624621"
        rpy="0 0 0" />
      <mass
        value="0.0900308275627489" />
      <inertia
        ixx="2.52108965590196E-05"
        ixy="-2.0664956290167E-05"
        ixz="-9.979423408339E-21"
        iyy="4.47942174809251E-05"
        iyz="-2.16491563912817E-21"
        izz="5.78162740600789E-05" />
    </inertial>
    <visual>
      <origin
        xyz="0 0 0"
        rpy="0 0 0" />
      <geometry>
        <mesh
          filename="model://provant_alpha_quadrotor/meshes/prop4.STL" />
      </geometry>
      <material
        name="">
        <color
          rgba="0.752941176470588 0.752941176470588 0.752941176470588 1" />
      </material>
    </visual>
    <collision>
      <origin
        xyz="0 0 0"
        rpy="0 0 0" />
      <geometry>
        <mesh
          filename="model://provant_alpha_quadrotor/meshes/prop4.STL" />
      </geometry>
    </collision>
  </link>
  <joint
    name="f4"
    type="continuous">
    <origin
      xyz="0 -0.3 0.2005"
      rpy="0 0 0" />
    <parent
      link="base_link" />
    <child
      link="prop4" />
    <axis
      xyz="0 0 -1" />
    <limit
      effort="0"
      velocity="0" />
  </joint>

  <!-- Defines the color of the links in gazebo -->
  <gazebo reference="base_link">
    <material>Gazebo/Red</material>
  </gazebo>

  <gazebo reference="legs">
    <material>Gazebo/Black</material>
  </gazebo>

  <gazebo reference="prop1">
    <material>Gazebo/White</material>
  </gazebo>

  <gazebo reference="prop2">
    <material>Gazebo/White</material>
  </gazebo>

  <gazebo reference="prop3">
    <material>Gazebo/White</material>
  </gazebo>

  <gazebo reference="prop4">
    <material>Gazebo/White</material>
  </gazebo>
  
  <!-- Loading the state and actuators plugins -->
  <gazebo>
    <plugin name="empuxo" filename="libgazebo_ros_QuadForces.so">
      <topic_F1>Empuxoh1</topic_F1>
      <topic_F2>Empuxoh2</topic_F2>
      <topic_F3>Empuxoh3</topic_F3>
      <topic_F4>Empuxoh4</topic_F4>
      <body>base_link</body>
      <Motor1>prop1</Motor1>
      <Motor2>prop2</Motor2>
      <Motor3>prop3</Motor3>
      <Motor4>prop4</Motor4>
      <DragCte>0.0179</DragCte>
    </plugin>
    <!--<plugin name="forces_1" filename="libgazebo_ros_brushless_plugin.so">
      <topic_FR>Empuxoh1</topic_FR>
      <LinkDir>prop1</LinkDir>
      <topic_FL>Empuxoh2</topic_FL>
      <LinkEsq>prop2</LinkEsq>
      <DragCte>0.0001</DragCte>
    </plugin>
    <plugin name="forces_2" filename="libgazebo_ros_brushless_plugin.so">
      <topic_FR>Empuxoh3</topic_FR>
      <LinkDir>prop3</LinkDir>
      <topic_FL>Empuxoh4</topic_FL>
      <LinkEsq>prop4</LinkEsq>
      <DragCte>0.0001</DragCte>
    </plugin>
    <plugin name="vetor_estados" filename="libgazebo_ros_QuadData.so">
      <NameOfTopic>Estados</NameOfTopic>
      <bodyName>base_link</bodyName>
      </plugin>-->
  </gazebo>

</robot>
