<robot
  name="quadcopter">
  <link
    name="main_body">
    <inertial>
      <origin
        xyz="1.6208E-10 -1.5103E-10 2.7915E-10"
        rpy="0 0 0" />
      <mass
        value="0.052451" />
      <inertia
        ixx="0.00010119"
        ixy="5.6493E-08"
        ixz="2.442E-14"
        iyy="0.00010119"
        iyz="-2.2727E-14"
        izz="0.00019415" />
    </inertial>
    <visual>
      <origin
        xyz="0 0 0"
        rpy="0 0 0" />
      <geometry>
        <mesh
          filename="package://Database/urdf/meshes/main_body.STL" />
      </geometry>
      <material
        name="">
        <color
          rgba="0.75294 0.75294 0.75294 1" />
      </material>
    </visual>
    <collision>
      <origin
        xyz="0 0 0"
        rpy="0 0 0" />
      <geometry>
        <mesh
          filename="package://Database/urdf/meshes/main_body.STL" />
      </geometry>
    </collision>
  </link>
    <link
    name="motor1">
    <inertial>
      <origin
        xyz="2.7756E-17 -2.7756E-17 2.7756E-17"
        rpy="0 0 0" />
      <mass
        value="0.0067333" />
      <inertia
        ixx="1.2162E-06"
        ixy="4.1395E-08"
        ixz="-4.4137E-19"
        iyy="6.3625E-07"
        iyz="-1.4697E-17"
        izz="9.6099E-07" />
    </inertial>
    <visual>
      <origin
        xyz="0 0 0"
        rpy="0 0 0" />
      <geometry>
        <mesh
          filename="package://Database/urdf/meshes/motor1.STL" />
      </geometry>
      <material
        name="">
        <color
          rgba="0.75294 0.75294 0.75294 1" />
      </material>
    </visual>
    <collision>
      <origin
        xyz="0 0 0"
        rpy="0 0 0" />
      <geometry>
        <mesh
          filename="package://Database/urdf/meshes/motor1.STL" />
      </geometry>
    </collision>
  </link>
  <joint
    name="prp1"
    type="revolute">
    <origin
      xyz="-0.12 0 0.0077966"
      rpy="-3.4915E-15 0 -0.7854" />
    <parent
      link="main_body" />
    <child
      link="motor1" />
    <axis
      xyz="0 0 1" />
    <limit
      lower="0"
      upper="31415"
      effort="0"
      velocity="0" />
  </joint>
  <link
    name="motor2">
    <inertial>
      <origin
        xyz="-5.5511E-17 -2.7756E-17 2.7756E-17"
        rpy="0 0 0" />
      <mass
        value="0.0067333" />
      <inertia
        ixx="9.2893E-07"
        ixy="-2.9263E-07"
        ixz="-4.4012E-19"
        iyy="9.2349E-07"
        iyz="-1.4699E-17"
        izz="9.6099E-07" />
    </inertial>
    <visual>
      <origin
        xyz="0 0 0"
        rpy="0 0 0" />
      <geometry>
        <mesh
          filename="package://Database/urdf/meshes/motor2.STL" />
      </geometry>
      <material
        name="">
        <color
          rgba="0.75294 0.75294 0.75294 1" />
      </material>
    </visual>
    <collision>
      <origin
        xyz="0 0 0"
        rpy="0 0 0" />
      <geometry>
        <mesh
          filename="package://Database/urdf/meshes/motor2.STL" />
      </geometry>
    </collision>
  </link>
  <joint
    name="prp2"
    type="revolute">
    <origin
      xyz="0 -0.12 0.0077966"
      rpy="-3.4915E-15 0 -0.7854" />
    <parent
      link="main_body" />
    <child
      link="motor2" />
    <axis
      xyz="0 0 1" />
    <limit
      lower="0"
      upper="31415"
      effort="0"
      velocity="0" />
  </joint>
  <link
    name="motor3">
    <inertial>
      <origin
        xyz="-5.5511E-17 -1.3878E-17 5.5511E-17"
        rpy="0 0 0" />
      <mass
        value="0.0067333" />
      <inertia
        ixx="1.2154E-06"
        ixy="-4.6293E-08"
        ixz="-4.4086E-19"
        iyy="6.3699E-07"
        iyz="-1.47E-17"
        izz="9.6099E-07" />
    </inertial>
    <visual>
      <origin
        xyz="0 0 0"
        rpy="0 0 0" />
      <geometry>
        <mesh
          filename="package://Database/urdf/meshes/motor3.STL" />
      </geometry>
      <material
        name="">
        <color
          rgba="0.75294 0.75294 0.75294 1" />
      </material>
    </visual>
    <collision>
      <origin
        xyz="0 0 0"
        rpy="0 0 0" />
      <geometry>
        <mesh
          filename="package://Database/urdf/meshes/motor3.STL" />
      </geometry>
    </collision>
  </link>
  <joint
    name="prp3"
    type="revolute">
    <origin
      xyz="0.12 0 0.0077966"
      rpy="-3.4915E-15 0 -0.7854" />
    <parent
      link="main_body" />
    <child
      link="motor3" />
    <axis
      xyz="0 0 1" />
    <limit
      lower="0"
      upper="31415"
      effort="0"
      velocity="0" />
  </joint>
  <link
    name="motor4">
    <inertial>
      <origin
        xyz="0 -4.1633E-17 5.5511E-17"
        rpy="0 0 0" />
      <mass
        value="0.0067333" />
      <inertia
        ixx="1.2172E-06"
        ixy="-3.346E-08"
        ixz="-4.4048E-19"
        iyy="6.3522E-07"
        iyz="-1.4698E-17"
        izz="9.6099E-07" />
    </inertial>
    <visual>
      <origin
        xyz="0 0 0"
        rpy="0 0 0" />
      <geometry>
        <mesh
          filename="package://Database/urdf/meshes/motor4.STL" />
      </geometry>
      <material
        name="">
        <color
          rgba="0.75294 0.75294 0.75294 1" />
      </material>
    </visual>
    <collision>
      <origin
        xyz="0 0 0"
        rpy="0 0 0" />
      <geometry>
        <mesh
          filename="package://Database/urdf/meshes/motor4.STL" />
      </geometry>
    </collision>
  </link>
  <joint
    name="prp4"
    type="revolute">
    <origin
      xyz="0 0.12 0.0077966"
      rpy="-3.4915E-15 0 -0.7854" />
    <parent
      link="main_body" />
    <child
      link="motor4" />
    <axis
      xyz="0 0 1" />
    <limit
      lower="0"
      upper="31415"
      effort="0"
      velocity="0" />
  </joint>

</robot>
