<?xml version="1.0" encoding="UTF-8"?>
<!--
This file is part of the ProVANT simulator project.
Licensed under the terms of the MIT open source license. More details at
https://github.com/Guiraffo/ProVANT-Simulator/blob/master/LICENSE.md
-->
<robot name="vant4_2">
  <link name="mainbody">
    <inertial>
      <origin xyz="-0.67395 0.00057188 0.089254" rpy="0 0 0" />
      <mass value="8.8099" />
      <inertia ixx="0.12931" ixy="-6.6594E-06" ixz="0.0014629" iyy="0.035152" iyz="-1.3178E-05" izz="0.14085" />
    </inertial>
    <visual>
      <origin xyz="0 0 0" rpy="0 0 0" />
      <geometry>
        <mesh filename="package://vant4_2/meshes/mainbody.STL" />
      </geometry>
      <material name="">
        <color rgba="0.79216 0.81961 0.93333 1" />
      </material>
    </visual>
    <collision>
      <origin xyz="0 0 0" rpy="0 0 0" />
      <geometry>
        <mesh filename="package://vant4_2/meshes/mainbody.STL" />
      </geometry>
    </collision>
  </link>
  <link name="RotorR">
    <inertial>
      <origin xyz="0.0043782 -0.0018844 -0.0072816" rpy="0 0 0" />
      <mass value="0.73962" />
      <inertia ixx="0.0013848" ixy="9.436E-06" ixz="5.8634E-08" iyy="0.0014698" iyz="-4.6609E-05" izz="0.00088418" />
    </inertial>
    <visual>
      <origin xyz="0 0 0" rpy="0 0 0" />
      <geometry>
        <mesh filename="package://vant4_2/meshes/RotorR.STL" />
      </geometry>
      <material name="">
        <color rgba="0.79216 0.81961 0.93333 1" />
      </material>
    </visual>
    <collision>
      <origin xyz="0 0 0" rpy="0 0 0" />
      <geometry>
        <mesh filename="package://vant4_2/meshes/RotorR.STL" />
      </geometry>
    </collision>
  </link>
  <joint name="rotR" type="revolute">
    <origin xyz="-0.6298 -1.0181 0.16308" rpy="0 0 0" />
    <parent link="mainbody" />
    <child link="RotorR" />
    <axis xyz="0 1 0" />
    <limit lower="-1.57" upper="1.57" effort="0" velocity="0" />
  </joint>
  <link name="HelR">
    <inertial>
      <origin xyz="-3.8933E-05 -0.0018231 -0.012888" rpy="0 0 0" />
      <mass value="0.12823" />
      <inertia ixx="0.00019712" ixy="-0.00046085" ixz="8.492E-05" iyy="0.0012571" iyz="3.1252E-05" izz="0.0014353" />
    </inertial>
    <visual>
      <origin xyz="0 0 0" rpy="0 0 0" />
      <geometry>
        <mesh filename="package://vant4_2/meshes/HelR.STL" />
      </geometry>
      <material name="">
        <color rgba="0.79216 0.81961 0.93333 1" />
      </material>
    </visual>
    <collision>
      <origin xyz="0 0 0" rpy="0 0 0" />
      <geometry>
        <mesh filename="package://vant4_2/meshes/HelR.STL" />
      </geometry>
    </collision>
  </link>
  <joint name="Hr" type="revolute">
    <origin xyz="0.0043832 -0.00027566 0.11308" rpy="0 0 0" />
    <parent link="RotorR" />
    <child link="HelR" />
    <axis xyz="0 0 1" />
    <limit lower="-1.57" upper="1.57" effort="0" velocity="0" />
  </joint>
  <link name="RotorL">
    <inertial>
      <origin xyz="-0.0043782 0.0018844 -0.0072816" rpy="0 0 0" />
      <mass value="0.73962" />
      <inertia ixx="0.0013848" ixy="9.4367E-06" ixz="-5.9349E-08" iyy="0.0014698" iyz="4.661E-05" izz="0.00088418" />
    </inertial>
    <visual>
      <origin xyz="0 0 0" rpy="0 0 0" />
      <geometry>
        <mesh filename="package://vant4_2/meshes/RotorL.STL" />
      </geometry>
      <material name="">
        <color rgba="0.79216 0.81961 0.93333 1" />
      </material>
    </visual>
    <collision>
      <origin xyz="0 0 0" rpy="0 0 0" />
      <geometry>
        <mesh filename="package://vant4_2/meshes/RotorL.STL" />
      </geometry>
    </collision>
  </link>
  <joint name="rotL" type="revolute">
    <origin xyz="-0.62106 1.0248 0.16369" rpy="0 0 0" />
    <parent link="mainbody" />
    <child link="RotorL" />
    <axis xyz="0 1 0" />
    <limit lower="-1.57" upper="1.57" effort="0" velocity="0" />
  </joint>
  <link name="HelL">
    <inertial>
      <origin xyz="-5.0975E-05 -0.0020058 -0.01286" rpy="0 0 0" />
      <mass value="0.12823" />
      <inertia ixx="3.2838E-05" ixy="0.00013904" ixz="1.5083E-08" iyy="0.0014156" iyz="-1.9717E-07" izz="0.0014411" />
    </inertial>
    <visual>
      <origin xyz="0 0 0" rpy="0 0 0" />
      <geometry>
        <mesh filename="package://vant4_2/meshes/HelL.STL" />
      </geometry>
      <material name="">
        <color rgba="0.79216 0.81961 0.93333 1" />
      </material>
    </visual>
    <collision>
      <origin xyz="0 0 0" rpy="0 0 0" />
      <geometry>
        <mesh filename="package://vant4_2/meshes/HelL.STL" />
      </geometry>
    </collision>
  </link>
  <joint name="Hl" type="revolute">
    <origin xyz="-0.0043832 0.00027566 0.11308" rpy="0 0 0" />
    <parent link="RotorL" />
    <child link="HelL" />
    <axis xyz="0 0 1" />
    <limit lower="-1.57" upper="1.57" effort="0" velocity="0" />
  </joint>
</robot>