<?xml version="1.0" encoding="utf-8"?>
<sdf version="1.6">
	<model name="vant_4">
    	<pose>0 0 0.116901904903541 0 0 0</pose>  <!-- do sist. coord. de ref com rel. ao global-->
    	<link name="Main_body">
      		<gravity>1</gravity>
      		<self_collide>0</self_collide>
      		<pose>0.00966124849608922 4.18332160756478E-05 -0.0453509303057282 0 0 -3.14159265358958</pose>  <!--pose com relação ao sist coord de ref--> <!--ou CM com rel ao ucs body-->
      		<must_be_base_link>1</must_be_base_link>
      		<velocity_decay>
        		<linear>0</linear>
        	<angular>0</angular>
      		</velocity_decay>
      		<inertial>
				<mass>3.92369179610077</mass>
				<pose>0 0 0 0 0 0</pose>
				<inertia>
				  		<ixx>0.142617029996685</ixx>
				  		<ixy>0.000107411356120632</ixy>
				  		<ixz>0.0165445855777232</ixz>
				  		<iyy>0.168781769741211</iyy>
				  		<iyz>3.19966471256658E-05</iyz>
				  		<izz>0.286208763277262</izz>
				</inertia>
			  </inertial>
      <collision name="Main_body_collision">
        <pose>-0.0196414769610056 4.18332160730827E-05 -0.0390509745978124 0 0 0</pose>
        <geometry>
          <mesh>
            <scale>1 1 1</scale>
            <uri>model://vant_4/meshes/Main_body_col.STL</uri>
          </mesh>
        </geometry>
        <surface>
          <contact>
            <ode />
          </contact>
          <friction>
            <ode>
              <mu>0</mu>
              <mu2>0</mu2>
            </ode>
          </friction>
        </surface>
      </collision>
      <visual name="Main_body_visual">
        <pose>-0.0196414769610056 4.18332160730827E-05 -0.0390509745978124 0 0 0</pose>
        <material>
          <ambient>1 0 0 1</ambient>
          <diffuse>1 1 0.5 1</diffuse>
        </material>
        <geometry>
          <mesh>
            <scale>1 1 1</scale>
            <uri>model://vant_4/meshes/Main_body.STL</uri>
          </mesh>
        </geometry>
      </visual>
    </link>
    <link name="Rotor_R">
      <gravity>1</gravity>
      <self_collide>0</self_collide>
      <pose>-0.0523818967062807 0.605031828840867 0.0263354861506355 0 0 -3.14159265358958</pose>
      <must_be_base_link>0</must_be_base_link>
      <velocity_decay>
        <linear>0</linear>
        <angular>0</angular>
      </velocity_decay>
      <inertial>
        <mass>0.265574384451818</mass>
        <pose>0 0 0 0 0 0</pose>
        <inertia>
          <ixx>0.000851833632811433</ixx>
          <ixy>8.38872446639087E-07</ixy>
          <ixz>1.36733268488383E-06</ixz>
          <iyy>0.000857908509123764</iyy>
          <iyz>6.98406284700382E-06</iyz>
          <izz>7.80008470857376E-05</izz>
        </inertia>
      </inertial>
      <collision name="Rotor_R_collision">
        <pose>-0.0816846221632441 0.605031828840878 -0.110737391054176 0 0 0</pose>
        <geometry>
          <mesh>
            <scale>1 1 1</scale>
            <uri>model://vant_4/meshes/Rotor_R_col.STL</uri>
          </mesh>
        </geometry>
        <surface>
          <contact>
            <ode />
          </contact>
          <friction>
            <ode>
              <mu>0</mu>
              <mu2>0</mu2>
            </ode>
          </friction>
        </surface>
      </collision>
      <visual name="Rotor_R_visual">
        <pose>-0.0816846221632441 0.605031828840878 -0.110737391054176 0 0 0</pose>
        <material>
          <ambient>1 0 0 1</ambient>
          <diffuse>1 0 0 1</diffuse>
        </material>
        <geometry>
          <mesh>
            <scale>1 1 1</scale>
            <uri>model://vant_4/meshes/Rotor_R.STL</uri>
          </mesh>
        </geometry>
      </visual>
    </link>
    <joint name="MainbodyRotorR" type="revolute">
      <parent>Main_body</parent>
      <child>Rotor_R</child>
      <pose>-0.00371621464518938 -2.35367281220533E-14 0.0127398156491012 0 0 0</pose>
      <axis>
        <xyz>-9.25812050203425E-12 1 -8.55973425719734E-13</xyz>
        <dynamics>
          <damping>0</damping>
          <friction>0</friction>
        </dynamics>
        <limit>
          <upper>1.57079633</upper>
          <lower>-1.57079633</lower>
          <effort>12</effort>
        </limit>
      </axis>
    </joint>
    <link name="Rotor_L">
      <gravity>1</gravity>
      <self_collide>0</self_collide>
      <pose>-0.053244214771937 -0.605096424275806 0.0266462965212636 0 0 -3.14159265358958</pose>
      <must_be_base_link>0</must_be_base_link>
      <velocity_decay>
        <linear>0</linear>
        <angular>0</angular>
      </velocity_decay>
      <inertial>
        <mass>0.264429481517308</mass>
        <pose>0 0 0 0 0 0</pose>
        <inertia>
          <ixx>0.000845900122790865</ixx>
          <ixy>1.30377876652612E-06</ixy>
          <ixz>5.1216438191027E-05</ixz>
          <iyy>0.000855455898193447</iyy>
          <iyz>6.96964712394107E-06</iyz>
          <izz>8.0942072132423E-05</izz>
        </inertia>
      </inertial>
      <collision name="Rotor_L_collision">
        <pose>-0.0825469402291633 -0.605096424275795 -0.111048201424804 0 0 0</pose>
        <geometry>
          <mesh>
            <scale>1 1 1</scale>
            <uri>model://vant_4/meshes/Rotor_L_col.STL</uri>
          </mesh>
        </geometry>
        <surface>
          <contact>
            <ode />
          </contact>
          <friction>
            <ode>
              <mu>0</mu>
              <mu2>0</mu2>
            </ode>
          </friction>
        </surface>
      </collision>
      <visual name="Rotor_L_visual">
        <pose>-0.0825469402291633 -0.605096424275795 -0.111048201424804 0 0 0</pose>
        <material>
          <ambient>1 0 0 1</ambient>
          <diffuse>1 0 0 1</diffuse>
        </material>
        <geometry>
          <mesh>
            <scale>1 1 1</scale>
            <uri>model://vant_4/meshes/Rotor_L.STL</uri>
          </mesh>
        </geometry>
      </visual>
    </link>
    <joint name="MainbodyRotorL" type="revolute">
      <parent>Main_body</parent>
      <child>Rotor_L</child>
      <pose>-0.00457857411726935 -2.79400148572861E-08 0.0124290179094951 0 0 0</pose>
      <axis>
        <xyz>-6.34453195097646E-17 1 5.14520401376288E-17</xyz>
        <dynamics>
          <damping>0</damping>
          <friction>0</friction>
        </dynamics>
        <limit>
          <upper>1.57079633</upper>
          <lower>-1.57079633</lower>
          <effort>12</effort>
        </limit>
      </axis>
    </joint>
    <link name="Rudder_R">
      <gravity>1</gravity>
      <self_collide>0</self_collide>
      <pose>0.445656330884181 -0.166808607906465 0.063513386217276 0 0 -3.14159265358958</pose>
      <must_be_base_link>0</must_be_base_link>
      <velocity_decay>
        <linear>0</linear>
        <angular>0</angular>
      </velocity_decay>
      <inertial>
        <mass>0.0248338730782767</mass>
        <pose>0 0 0 0 0 0</pose>
        <inertia>
          <ixx>0.00012709808900922</ixx>
          <ixy>1.35710238457544E-05</ixy>
          <ixz>7.74329833829202E-06</ixz>
          <iyy>3.3448065183759E-05</iyy>
          <iyz>5.42132570804282E-05</iyz>
          <izz>9.95024757063301E-05</izz>
        </inertia>
      </inertial>
      <collision name="Rudder_R_collision">
        <pose>0.41635360542705 -0.166808607906562 -0.147915291120817 0 0 0</pose>
        <geometry>
          <mesh>
            <scale>1 1 1</scale>
            <uri>model://vant_4/meshes/Rudder_R_col.STL</uri>
          </mesh>
        </geometry>
        <surface>
          <contact>
            <ode />
          </contact>
          <friction>
            <ode>
              <mu>0</mu>
              <mu2>0</mu2>
            </ode>
          </friction>
        </surface>
      </collision>
      <visual name="Rudder_R_visual">
        <pose>0.41635360542705 -0.166808607906562 -0.147915291120817 0 0 0</pose>
        <material>
          <ambient>0 0 0.75 1</ambient>
          <diffuse>0 0 0.75 1</diffuse>
        </material>
        <geometry>
          <mesh>
            <scale>1 1 1</scale>
            <uri>model://vant_4/meshes/Rudder_R.STL</uri>
          </mesh>
        </geometry>
      </visual>
    </link>
    <joint name="MainbodyRudderR" type="revolute">
      <parent>Main_body</parent>
      <child>Rudder_R</child>
      <pose>0.00843624062587656 0.00133813367236219 -0.000331457942643637 0 0.50744770815185 4.20100754056477</pose>
      <axis>
        <xyz>0.845570837344557 0.526912929820461 -0.0858645644049038</xyz>
        <dynamics>
          <damping>0</damping>
          <friction>0</friction>
        </dynamics>
        <limit>
          <upper>0.785398</upper>
          <lower>-0.785398</lower>
          <effort>1</effort>
        </limit>
      </axis>
    </joint>
    <link name="Rudder_L">
      <gravity>1</gravity>
      <self_collide>0</self_collide>
      <pose>0.445607332577239 0.167918093138838 0.0615472814614074 0 0 -3.14159265358958</pose>
      <must_be_base_link>0</must_be_base_link>
      <velocity_decay>
        <linear>0</linear>
        <angular>0</angular>
      </velocity_decay>
      <inertial>
        <mass>0.0248338869687102</mass>
        <pose>0 0 0 0 0 0</pose>
        <inertia>
          <ixx>0.000127109722229028</ixx>
          <ixy>1.36988525530104E-05</ixy>
          <ixz>7.5106807259205E-06</ixz>
          <iyy>3.33318045581811E-05</iyy>
          <iyz>5.41399146925325E-05</iyz>
          <izz>9.9607228240173E-05</izz>
        </inertia>
      </inertial>
      <collision name="Rudder_L_collision">
        <pose>0.416304607120181 0.167918093138741 -0.145949186364948 0 0 0</pose>
        <geometry>
          <mesh>
            <scale>1 1 1</scale>
            <uri>model://vant_4/meshes/Rudder_L_col.STL</uri>
          </mesh>
        </geometry>
        <surface>
          <contact>
            <ode />
          </contact>
          <friction>
            <ode>
              <mu>0</mu>
              <mu2>0</mu2>
            </ode>
          </friction>
        </surface>
      </collision>
      <visual name="Rudder_L_visual">
        <pose>0.416304607120181 0.167918093138741 -0.145949186364948 0 0 0</pose>
        <material>
          <ambient>0 0 0.75 1</ambient>
          <diffuse>0 0 0.75 1</diffuse>
        </material>
        <geometry>
          <mesh>
            <scale>1 1 1</scale>
            <uri>model://vant_4/meshes/Rudder_L.STL</uri>
          </mesh>
        </geometry>
      </visual>
    </link>
    <joint name="MainbodyRudderL" type="revolute">
      <parent>Main_body</parent>
      <child>Rudder_L</child>
      <pose>0.00838729688893219 -0.000228248861754654 0.00163442258027313 0 5.77573759902802 5.22377042020436</pose>
      <axis>
        <xyz>0.84557083734437 -0.526912929820753 0.0858645644049498</xyz>
        <dynamics>
          <damping>0</damping>
          <friction>0</friction>
        </dynamics>
        <limit>
          <upper>0.785398</upper>
          <lower>-0.785398</lower>
          <effort>1</effort>
        </limit>
      </axis>
    </joint>
    <link name="Aileron_R">
      <gravity>1</gravity>
      <self_collide>0</self_collide>
      <pose>0.0219052425576024 0.352867701469059 0.0199782931129107 0 0 -3.14159265358958</pose>
      <must_be_base_link>0</must_be_base_link>
      <velocity_decay>
        <linear>0</linear>
        <angular>0</angular>
      </velocity_decay>
      <inertial>
        <mass>0.0158270885417719</mass>
        <pose>0 0 0 0 0 0</pose>
        <inertia>
          <ixx>1.22617495276087E-05</ixx>
          <ixy>8.82281479854416E-07</ixy>
          <ixz>6.13887987928609E-08</ixz>
          <iyy>1.06939436387387E-06</iyy>
          <iyz>9.38972773414572E-07</iyz>
          <izz>1.30222119899012E-05</izz>
        </inertia>
      </inertial>
      <collision name="Aileron_R_collision">
        <pose>-0.00739748289941574 0.352867701469054 -0.104380198016451 0 0 0</pose>
        <geometry>
          <mesh>
            <scale>1 1 1</scale>
            <uri>model://vant_4/meshes/Aileron_R_col.STL</uri>
          </mesh>
        </geometry>
        <surface>
          <contact>
            <ode />
          </contact>
          <friction>
            <ode>
              <mu>0</mu>
              <mu2>0</mu2>
            </ode>
          </friction>
        </surface>
      </collision>
      <visual name="Aileron_R_visual">
        <pose>-0.00739748289941574 0.352867701469054 -0.104380198016451 0 0 0</pose>
        <material>
          <ambient>0 1 0 1</ambient>
          <diffuse>0 1 0 1</diffuse>
        </material>
        <geometry>
          <mesh>
            <scale>1 1 1</scale>
            <uri>model://vant_4/meshes/Aileron_R.STL</uri>
          </mesh>
        </geometry>
      </visual>
    </link>
    <joint name="MainbodyAileronR" type="revolute">
      <parent>Main_body</parent>
      <child>Aileron_R</child>
      <pose>0.00872958973248779 2.61964092954092E-05 -0.000207576246831112 0 0.0821479619814961 1.65294529417143</pose>
      <axis>
        <xyz>0.997042353041106 -0.0768536722859088 -0.000243512681063998</xyz>
        <dynamics>
          <damping>0</damping>
          <friction>0</friction>
        </dynamics>
        <limit>
          <upper>0.523599</upper>
          <lower>-0.523599</lower>
          <effort>1</effort>
        </limit>
      </axis>
    </joint>
    <link name="Aileron_L">
      <gravity>1</gravity>
      <self_collide>0</self_collide>
      <pose>0.0216185519034385 -0.352872102850549 0.019493622684778 0 0 -3.14159265358958</pose>
      <must_be_base_link>0</must_be_base_link>
      <velocity_decay>
        <linear>0</linear>
        <angular>0</angular>
      </velocity_decay>
      <inertial>
        <mass>0.0158285635591445</mass>
        <pose>0 0 0 0 0 0</pose>
        <inertia>
          <ixx>1.22744126401554E-05</ixx>
          <ixy>8.29411677117579E-07</ixy>
          <ixz>1.0234666836338E-07</ixz>
          <iyy>1.0694722197982E-06</iyy>
          <iyz>9.85824517044126E-07</iyz>
          <izz>1.30170687520763E-05</izz>
        </inertia>
      </inertial>
      <collision name="Aileron_L_collision">
        <pose>-0.00768417355373305 -0.352872102850554 -0.103895527588319 0 0 0</pose>
        <geometry>
          <mesh>
            <scale>1 1 1</scale>
            <uri>model://vant_4/meshes/Aileron_L_col.STL</uri>
          </mesh>
        </geometry>
        <surface>
          <contact>
            <ode />
          </contact>
          <friction>
            <ode>
              <mu>0</mu>
              <mu2>0</mu2>
            </ode>
          </friction>
        </surface>
      </collision>
      <visual name="Aileron_L_visual">
        <pose>-0.00768417355373305 -0.352872102850554 -0.103895527588319 0 0 0</pose>
        <material>
          <ambient>0 1 0 1</ambient>
          <diffuse>0 1 0 1</diffuse>
        </material>
        <geometry>
          <mesh>
            <scale>1 1 1</scale>
            <uri>model://vant_4/meshes/Aileron_L.STL</uri>
          </mesh>
        </geometry>
      </visual>
    </link>
    <joint name="MainbodyAileronL" type="revolute">
      <parent>Main_body</parent>
      <child>Aileron_L</child>
      <pose>0.00872856948777765 -2.62128853639187E-05 0.000268046340012471 0 6.20088950138841 1.48850051194882</pose>
      <axis>
        <xyz>0.99667675788083 0.0814577507974207 0.000274107975471852</xyz>
        <dynamics>
          <damping>0</damping>
          <friction>0</friction>
        </dynamics>
        <limit>
          <upper>0.523599</upper>
          <lower>-0.523599</lower>
          <effort>1</effort>
        </limit>
      </axis>
    </joint> -->
    <link name="Hel_R">
      <gravity>1</gravity>
      <self_collide>0</self_collide>
      <pose>-0.053612241515273 0.606010963307966 0.127751107725581 0 0 -3.14159265358958</pose>
      <must_be_base_link>0</must_be_base_link>
      <velocity_decay>
        <linear>0</linear>
        <angular>0</angular>
      </velocity_decay>
      <inertial>
        <mass>0.0170125543615066</mass>
        <pose>0 0 0 0 0 0</pose>
        <inertia>
          <ixx>2.62686958429158E-05</ixx>
          <ixy>3.14284300705122E-10</ixy>
          <ixz>4.03954211257664E-07</ixz>
          <iyy>2.62615943442783E-05</iyy>
          <iyz>4.57993741626849E-14</iyz>
          <izz>5.24361179824439E-05</izz>
        </inertia>
      </inertial>
      <collision name="Hel_R_collision">
        <pose>-0.0829149669722361 0.606010963307977 -0.212153012629121 0 0 0</pose>
        <geometry>
          <mesh>
            <scale>1 1 1</scale>
            <uri>model://vant_4/meshes/Hel_R_col.STL</uri>
          </mesh>
        </geometry>
        <surface>
          <contact>
            <ode />
          </contact>
          <friction>
            <ode>
              <mu>0</mu>
              <mu2>0</mu2>
            </ode>
          </friction>
        </surface>
      </collision>
      <visual name="Hel_R_visual">
        <pose>-0.0829149669722361 0.606010963307977 -0.212153012629121 0 0 0</pose>
       <material>
     <ambient>0 0 0.75 1</ambient>
     <diffuse>0 0 0.75 1</diffuse>>
        </material>
        <geometry>
          <mesh>
            <scale>1 1 1</scale>
            <uri>model://vant_4/meshes/Hel_R.STL</uri>
          </mesh>
        </geometry>
      </visual>
    </link>
    <joint name="Rotor_R-Hel_R" type="revolute">
      <parent>Rotor_R</parent>
      <child>Hel_R</child>
      <pose>6.36783241095285E-07 -7.88783997335285E-05 4.44309018993172E-07 0 0 0</pose>
      <axis>
        <xyz>0.0154310998556102 -0.00550750412008058 -0.999865765268325</xyz>
        <dynamics>
          <damping>0</damping>
          <friction>0</friction>
        </dynamics>
        <limit>
          <effort>1</effort>
        </limit>
      </axis>
    </joint>
    <link name="Hel_L">
      <gravity>1</gravity>
      <self_collide>0</self_collide>
      <pose>-0.0475557913720434 -0.606009216446499 0.127744684283205 0 0 -3.14159265358958</pose>
      <must_be_base_link>0</must_be_base_link>
      <velocity_decay>
        <linear>0</linear>
        <angular>0</angular>
      </velocity_decay>
      <inertial>
        <mass>0.0170131604983856</mass>
        <pose>0 0 0 0 0 0</pose>
        <inertia>
          <ixx>2.6445427449782E-05</ixx>
          <ixy>3.83340707333828E-10</ixy>
          <ixz>2.1835854377317E-06</ixz>
          <iyy>2.62630002982568E-05</iyy>
          <iyz>2.86011224014583E-11</iyz>
          <izz>5.22599188946056E-05</izz>
        </inertia>
      </inertial>
      <collision name="Hel_L_collision">
        <pose>-0.0768585168292699 -0.606009216446489 -0.212146589186746 0 0 0</pose>
        <geometry>
          <mesh>
            <scale>1 1 1</scale>
            <uri>model://vant_4/meshes/Hel_L_col.STL</uri>
          </mesh>
        </geometry>
        <surface>
          <contact>
            <ode />
          </contact>
          <friction>
            <ode>
              <mu>0</mu>
              <mu2>0</mu2>
            </ode>
          </friction>
        </surface>
      </collision>
      <visual name="Hel_L_visual">
        <pose>-0.0768585168292699 -0.606009216446489 -0.212146589186746 0 0 0</pose>
        <material>
          <ambient>0 0 0.75 1</ambient>
          <diffuse>0 0 0.75 1</diffuse>
        </material>
        <geometry>
          <mesh>
            <scale>1 1 1</scale>
            <uri>model://vant_4/meshes/Hel_L.STL</uri>
          </mesh>
        </geometry>
      </visual>
    </link>
    <joint name="Rotor_L-Hel_L" type="revolute">
      <parent>Rotor_L</parent>
      <child>Hel_L</child>
      <pose>0.000129274005485111 8.99128848671493E-05 -0.00154272576791425 0 0 0</pose>
      <axis>
        <xyz>-0.0836945375710494 -0.00550750412008107 0.996476237438272</xyz>
        <dynamics>
          <damping>0</damping>
          <friction>0</friction>
        </dynamics>
        <limit>
          <effort>1</effort>
        </limit>
      </axis>
    </joint>
    <plugin name="empuxo"
filename="libgazebo_ros_brushless_plugin.so">
            <topic_FR>Thrustdir</topic_FR>
            <LinkDir>Hel_R</LinkDir>
            <topic_FL>Thrustesq</topic_FL>
            <LinkEsq>Hel_L</LinkEsq>
            <DragCte>0.0001</DragCte>
     </plugin>
   <!--  <plugin name="VetorEstados"
filename="libgazebo_ros_AllData_plugin.so">
            <NameOfTopic>Estados</NameOfTopic>
            <NameOfJointR>MainbodyRotorR</NameOfJointR>
            <NameOfJointL>MainbodyRotorL</NameOfJointL>
            <bodyName>Main_body</bodyName>
     </plugin> -->
     <plugin name="RotorRplugin"
filename="libgazebo_ros_servo_motor_plugin.so">
            <NameOfJoint>MainbodyRotorR</NameOfJoint>   
            <TopicPublisher>RotorR</TopicPublisher>
            <TopicSubscriber>RefRotorR</TopicSubscriber>
            <Modo>Torque</Modo>
     </plugin>
     <plugin name="RotorLplugin"
filename="libgazebo_ros_servo_motor_plugin.so">
            <NameOfJoint>MainbodyRotorL</NameOfJoint>
            <TopicPublisher>RotorL</TopicPublisher>
            <TopicSubscriber>RefRotorL</TopicSubscriber>
            <Modo>Torque</Modo>
     </plugin>
     <plugin name="AileronLplugin"
filename="libgazebo_ros_servo_motor_plugin.so">
            <NameOfJoint>MainbodyAileronL</NameOfJoint>
            <TopicPublisher>AileronL</TopicPublisher>
            <TopicSubscriber>RefAileronL</TopicSubscriber>
            <Modo>Torque</Modo>
     </plugin>  
      <plugin name="AileronRplugin"
filename="libgazebo_ros_servo_motor_plugin.so">
            <NameOfJoint>MainbodyAileronR</NameOfJoint>
            <TopicPublisher>AileronR</TopicPublisher>
            <TopicSubscriber>RefAileronR</TopicSubscriber>
            <Modo>Torque</Modo>
     </plugin>
      <plugin name="RudderLplugin"
filename="libgazebo_ros_servo_motor_plugin.so">
            <NameOfJoint>MainbodyRudderL</NameOfJoint>
            <TopicPublisher>RudderL</TopicPublisher>
            <TopicSubscriber>RefRudderL</TopicSubscriber>
            <Modo>Torque</Modo>
     </plugin>
     <plugin name="RudderRplugin"
filename="libgazebo_ros_servo_motor_plugin.so">
            <NameOfJoint>MainbodyRudderR</NameOfJoint>
            <TopicPublisher>RudderR</TopicPublisher>
            <TopicSubscriber>RefRudderR</TopicSubscriber>
            <Modo>Torque</Modo>
    </plugin>-->
  </model>
</sdf>
