<sdf version='1.6'>
  <model name='quadcopter'>
    <link name='main_body'>
      <pose frame=''>0 0 0 0 -0 0</pose>
      <inertial>
        <pose frame=''>0 -0 0 0 -0 0</pose>
        <mass>2.24</mass>
        <inertia>
          <ixx>0.0384</ixx>
          <ixy>5.6493e-18</ixy>
          <ixz>2.442e-18</ixz>
          <iyy>0.0384</iyy>
          <iyz>-2.2727e-18</iyz>
          <izz>0.0615</izz>
        </inertia>
      </inertial>
      <collision name='main_body_collision'>
        <pose frame=''>0 0 0 0 -0 0</pose>
        <geometry>
          <mesh>
            <scale>1 1 1</scale>
            <uri>model://quadcopter/meshes/main_body.STL</uri>
          </mesh>
        </geometry>
      </collision>
      <visual name='main_body_visual'>
        <pose frame=''>0 0 0 0 -0 0</pose>
        <geometry>
          <mesh>
            <scale>1 1 1</scale>
            <uri>model://quadcopter/meshes/main_body_urss.dae</uri>
          </mesh>
        </geometry>
      </visual>
    </link>
    <link name='motor3'>
      <pose frame=''>-0.12 0 0.0 -0 -0 -0</pose>	<!--0.7854-->
      <inertial>
        <pose frame=''>0 -0 0 0 -0 0</pose>
        <mass>0.00007333</mass>
        <inertia>
           <ixx>1.2172e-19</ixx>
          <ixy>-3.346e-19</ixy>
          <ixz>-4.4048e-19</ixz>
          <iyy>6.3522e-19</iyy>
          <iyz>-1.4698e-19</iyz>
          <izz>9.6099e-19</izz>
        </inertia>
      </inertial>
      <collision name='motor3_collision'>
        <pose frame=''>0 0 0 0 -0 0</pose>
        <geometry>
          <mesh>
            <scale>1 1 1</scale>
            <uri>model://quadcopter/meshes/motor1.STL</uri>
          </mesh>
        </geometry>
      </collision>
      <visual name='motor3_visual'>
        <pose frame=''>0 0 0 0 -0 0</pose>
        <geometry>
          <mesh>
            <scale>1 1 1</scale>
            <uri>model://quadcopter/meshes/motor1urss.dae</uri>
          </mesh>
        </geometry>
      </visual>
    </link>
    <joint name='prp3' type='revolute'>
      <child>motor1</child>
      <parent>main_body</parent>
      <axis>
        <xyz>0 0 1</xyz>
        <limit>
         <!--<lower>0</lower>
          <upper>inf</upper>-->
          <effort>0</effort>
          <velocity>0</velocity>
        </limit>
        <dynamics>
          <spring_reference>0</spring_reference>
          <spring_stiffness>0</spring_stiffness>
        </dynamics>
        <use_parent_model_frame>1</use_parent_model_frame>
      </axis>
    </joint>
    <link name='motor4'>
      <pose frame=''>0 -0.12 0.0 -0 -0 -0</pose>
      <inertial>
        <pose frame=''>-0 -0 0 0 -0 0</pose>
        <mass>0.00007333</mass>
        <inertia>
           <ixx>1.2172e-19</ixx>
          <ixy>-3.346e-19</ixy>
          <ixz>-4.4048e-19</ixz>
          <iyy>6.3522e-19</iyy>
          <iyz>-1.4698e-19</iyz>
          <izz>9.6099e-19</izz>
        </inertia>
      </inertial>
      <collision name='motor4_collision'>
        <pose frame=''>0 0 0 0 -0 0</pose>
        <geometry>
          <mesh>
            <scale>1 1 1</scale>
            <uri>model://quadcopter/meshes/motor2.STL</uri>
          </mesh>
        </geometry>
      </collision>
      <visual name='motor4_visual'>
        <pose frame=''>0 0 0 0 -0 0</pose>
        <geometry>
          <mesh>
            <scale>1 1 1</scale>
            <uri>model://quadcopter/meshes/motor2urss.dae</uri>
          </mesh>
        </geometry>
      </visual>
    </link>
    <joint name='prp4' type='revolute'>
      <child>motor2</child>
      <parent>main_body</parent>
      <axis>
        <xyz>0 0 1</xyz>
        <limit>
         <!--<lower>0</lower>
          <upper>inf</upper>-->
          <effort>0</effort>
          <velocity>0</velocity>
        </limit>
        <dynamics>
          <spring_reference>0</spring_reference>
          <spring_stiffness>0</spring_stiffness>
        </dynamics>
        <use_parent_model_frame>1</use_parent_model_frame>
      </axis>
    </joint>
    <link name='motor1'>
      <pose frame=''>0.12 0 0.0 -0 -0 -0</pose>
      <inertial>
        <pose frame=''>-0 -0 0 0 -0 0</pose>
        <mass>0.00007333</mass>
        <inertia>
          <ixx>1.2172e-19</ixx>
          <ixy>-3.346e-19</ixy>
          <ixz>-4.4048e-19</ixz>
          <iyy>6.3522e-19</iyy>
          <iyz>-1.4698e-19</iyz>
          <izz>9.6099e-19</izz>
        </inertia>
      </inertial>
      <collision name='motor1_collision'>
        <pose frame=''>0 0 0 0 -0 0</pose>
        <geometry>
          <mesh>
            <scale>1 1 1</scale>
            <uri>model://quadcopter/meshes/motor3.STL</uri>
          </mesh>
        </geometry>
      </collision>
      <visual name='motor1_visual'>
        <pose frame=''>0 0 0 0 -0 0</pose>
        <geometry>
          <mesh>
            <scale>1 1 1</scale>
            <uri>model://quadcopter/meshes/motor3urss.dae</uri>
          </mesh>
        </geometry>
      </visual>
    </link>
    <joint name='prp1' type='revolute'>
      <child>motor3</child>
      <parent>main_body</parent>
      <axis>
        <xyz>0 0 1</xyz>
        <limit>
          <!--<lower>0</lower>
          <upper>inf</upper>-->
          <effort>0</effort>
          <velocity>0</velocity>
        </limit>
        <dynamics>
          <spring_reference>0</spring_reference>
          <spring_stiffness>0</spring_stiffness>
        </dynamics>
        <use_parent_model_frame>1</use_parent_model_frame>
      </axis>
    </joint>
    <link name='motor2'>
      <pose frame=''>0 0.12 0.0 -0 -0 -0</pose>
      <inertial>
        <pose frame=''>0 -0 0 0 -0 0</pose>
        <mass>0.00007333</mass>
        <inertia>
          <ixx>1.2172e-19</ixx>
          <ixy>-3.346e-19</ixy>
          <ixz>-4.4048e-19</ixz>
          <iyy>6.3522e-19</iyy>
          <iyz>-1.4698e-19</iyz>
          <izz>9.6099e-19</izz>
        </inertia>
      </inertial>
      <collision name='motor2_collision'>
        <pose frame=''>0 0 0 0 -0 0</pose>
        <geometry>
          <mesh>
            <scale>1 1 1</scale>
            <uri>model://quadcopter/meshes/motor4.STL</uri>
          </mesh>
        </geometry>
      </collision>
      <visual name='motor2_visual'>
        <pose frame=''>0 0 0 0 -0 0</pose>
        <geometry>
          <mesh>
            <scale>1 1 1</scale>
            <uri>model://quadcopter/meshes/motor4urss.dae</uri>
          </mesh>
        </geometry>
      </visual>
    </link>
    <joint name='prp2' type='revolute'>
      <child>motor4</child>
      <parent>main_body</parent>
      <axis>
        <xyz>0 0 1</xyz>
        <limit>
          <!--<lower>0</lower>
          <upper>inf</upper>-->
          <effort>0</effort>	
          <velocity>0</velocity>
        </limit>
        <dynamics>
          <spring_reference>0</spring_reference>
          <spring_stiffness>0</spring_stiffness>
        </dynamics>
        <use_parent_model_frame>1</use_parent_model_frame>
      </axis>
    </joint>
<!--    <plugin name="empuxo"
filename="libgazebo_ros_brushless_plugin.so">
            <topic_FR>Empuxoh1</topic_FR>
            <LinkDir>motor1</LinkDir>
            <topic_FL>Empuxoh2</topic_FL>
            <LinkEsq>motor2</LinkEsq>
            <DragCte>0.0179</DragCte>
     	  </plugin> 
     <plugin name="empuxo"
filename="libgazebo_ros_brushless_plugin.so">
            <topic_FR>Empuxoh3</topic_FR>
            <LinkDir>motor3</LinkDir>
            <topic_FL>Empuxoh4</topic_FL>
            <LinkEsq>motor4</LinkEsq>
            <DragCte>0.0179</DragCte>
         </plugin> -->
  
     <plugin name="empuxo"
filename="libgazebo_ros_QuadForces.so">
            <topic_F1>Empuxoh1</topic_F1>
            <topic_F2>Empuxoh2</topic_F2>
            <topic_F3>Empuxoh3</topic_F3>
            <topic_F4>Empuxoh4</topic_F4>
            <body> main_body </body>
            <Motor1>motor1</Motor1>
            <Motor2>motor2</Motor2>
            <Motor3>motor3</Motor3>
            <Motor4>motor4</Motor4>
            <DragCte>0.0179</DragCte>    
     	  </plugin> 
     
      <plugin name="VetorEstados"
filename="libgazebo_ros_QuadData.so">
            <NameOfTopic>Estados</NameOfTopic>
            <bodyName>main_body</bodyName>
     </plugin>
     <plugin name="PathPlotter"
filename="libgazebo_ros_PathPlotter.so">
            <NameOfPathTopic>Path</NameOfPathTopic>
            <NameOfMarkerTopic>marker</NameOfMarkerTopic>
            <NameOfPathRefTopic>path_ref</NameOfPathRefTopic>
            <bodyName>main_body</bodyName>
            <uav>quadcopter</uav>
     </plugin> 
     <plugin name="VisualPropellersQuad_13"
filename="libgazebo_ros_VisualPropellers.so">
            <Propeller1>prp1</Propeller1>
            <Propeller2>prp3</Propeller2>
            <Propellers_Velocity>30</Propellers_Velocity>
     </plugin>
     <plugin name="VisualPropellersQuad_24"
filename="libgazebo_ros_VisualPropellers.so">
            <Propeller1>prp2</Propeller1>
            <Propeller2>prp4</Propeller2>
            <Propellers_Velocity>-30</Propellers_Velocity>
     </plugin>       
  </model>
</sdf>
