<?xml version="1.0" encoding="UTF-8"?>
<sdf version="1.6">
    <model name="modelo">
        <link name="main_body">
            <pose>0 0 0 0 -0 0</pose>
            <inertial>
                <mass>1.49981</mass>
                <pose>0 0 0 0 -0 0</pose>
                <inertia>
                    <ixx>0.0478834</ixx>
                    <ixy>0</ixy>
                    <ixz>0</ixz>
                    <iyy>0.0227521</iyy>
                    <iyz>0</iyz>
                    <izz>0.0606231</izz>
                </inertia>
            </inertial>
            <visual name="main_body_visual">
                <pose>0 0 0 0 -0 0</pose>
                <geometry>
                    <box>
                        <size>1 1 1</size>
                    </box>
                </geometry>
                <material>
                    <ambient>1 1 1 0.6 </ambient>
                    <diffuse>1 1 1 0.6 </diffuse>
                    <specular>1 1 1 0.6</specular>
                    <emissive>0 0 0 0</emissive>
                </material>
            </visual>
        </link>
        <link name="main_body2">
            <pose>1 0 0 0 -0 0</pose>
            <!--<inertial>
                <mass>1.49981</mass>
                <pose>0 0 0 0 -0 0</pose>
                <inertia>
                    <ixx>0.0478834</ixx>
                    <ixy>0</ixy>
                    <ixz>0</ixz>
                    <iyy>0.0227521</iyy>
                    <iyz>0</iyz>
                    <izz>0.0606231</izz>
                </inertia>
            </inertial>-->
            <inertial>
                <mass>0.0809439719362664</mass>
                <pose>-3.60859273452335E-10 -0.000226380714807978 0.0594780519701684 0 0 0</pose>
                <inertia>
                    <ixx>3.88267747087835E-06</ixx>
                    <ixy>0</ixy>
                    <ixz>0</ixz>
                    <iyy>0.000104858690365283</iyy>
                    <iyz>0</iyz>
                    <izz>8.31755564684115E-05</izz>
                </inertia>
            </inertial>
            <visual name="main_body_visual">
                <pose>0 0 0 0 -0 0</pose>
                <geometry>
                    <box>
                        <size>1 1 1</size>
                    </box>
                </geometry>
                <material>
                    <ambient>1 1 1 0.6 </ambient>
                    <diffuse>1 1 1 0.6 </diffuse>
                    <specular>1 1 1 0.6</specular>
                    <emissive>0 0 0 0</emissive>
                </material>
            </visual>
        </link>
        <joint name="aL" type="revolute">
            <pose>-1 0 0 0 0 0</pose>
            <parent>main_body</parent>
            <child>main_body2</child>
            <axis>
                <xyz>0 1 0</xyz>
                <dynamics>
                    <damping>0.003</damping>
                    <friction>0</friction>
                </dynamics>
            </axis>
        </joint>
        <joint name="fixed to ground" type="fixed">
			  <parent>world</parent>
			  <child>main_body</child>
        </joint>
        <plugin name="dados2" filename=" libgazebo_ros_universaljoint.so">
            <NameOfTopic>dados2</NameOfTopic>
            <NameOfJoint>aL</NameOfJoint>
            <Axis>axis</Axis>
        </plugin>
        <plugin name="elevplugin" filename="libgazebo_ros_servo2_motor_plugin.so">
            <NameOfJoint>aL</NameOfJoint>
            <Modo>Torque</Modo>
            <TopicSubscriber>juntasub</TopicSubscriber>
            <TopicPublisher>juntapub</TopicPublisher>
        </plugin>
    </model>
</sdf>
