<?xml version="1.0" encoding="UTF-8"?>
<sdf version='1.6'>
	<model name='vant4'>
		<link name='body'>
			<pose frame=''>0 0 0 0 -0 0</pose>
			<inertial>
				<pose frame=''>0.019587 -4.2e-05 0.039392 0 -0 0</pose>
				<mass>6.9602</mass>
				<inertia>
					<ixx>0.14735</ixx>
					<ixy>-0.00010738</ixy>
					<ixz>0.016569</ixz>
					<iyy>0.16894</iyy>
					<iyz>3.1935e-05</iyz>
					<izz>0.2908</izz>
				</inertia>
			</inertial>
			<collision name='body_collision'>
				<pose frame=''>0 0 0 0 -0 0</pose>
				<geometry>
					<mesh>
						<scale>1 1 1</scale>
						<uri>model://vant4/meshes/body.STL</uri>
					</mesh>
				</geometry>
			</collision>
			<visual name='body_visual'>
				<pose frame=''>0 0 0 0 -0 0</pose>
				<geometry>
					<mesh>
						<scale>1 1 1</scale>
						<uri>model://vant4/meshes/body.STL</uri>
					</mesh>
				</geometry>
                <material>
                    <ambient>.3 .3 .3 1</ambient>
                    <diffuse>.3 .3 .3 1</diffuse>
                    <specular>1 1 1 1</specular>
                    <emissive>0 0 0 0</emissive>
                </material>
			</visual>
		</link>
		<link name='rotor_L'>
			<pose frame=''>0.077968 0.60727 0.12348 0 -0 0</pose>
			<inertial>
				<pose frame=''>0.004934 -0.001671 0.036978 0 -0 0</pose>
				<mass>0.51878</mass>
				<inertia>
					<ixx>0.0023873</ixx>
					<ixy>-4.249e-06</ixy>
					<ixz>-4.9216e-05</ixz>
					<iyy>0.0024908</iyy>
					<iyz>-3.8495e-06</iyz>
					<izz>0.00032922</izz>
				</inertia>
			</inertial>
			<collision name='rotor_L_collision'>
				<pose frame=''>0 0 0 0 -0 0</pose>
				<geometry>
					<mesh>
						<scale>1 1 1</scale>
						<uri>model://vant4/meshes/rotor_L.STL</uri>
					</mesh>
				</geometry>
			</collision>
			<collision name='motor_L_collision'>
				<pose frame=''>0 0 0 0 -0 0</pose>
				<geometry>
					<mesh>
						<scale>1 1 1</scale>
						<uri>model://vant4/meshes/motor_L.STL</uri>
					</mesh>
				</geometry>
			</collision>
			<visual name='rotor_L_visual'>
				<pose frame=''>0 0 0 0 -0 0</pose>
				<geometry>
					<mesh>
						<scale>1 1 1</scale>
						<uri>model://vant4/meshes/rotor_L.STL</uri>
					</mesh>
				</geometry>
                <material>
                    <ambient>.4 .4 .5 1</ambient>
                    <diffuse>.4 .4 .5 1</diffuse>
                    <specular>1 1 1 1</specular>
                    <emissive>0 0 0 0</emissive>
                </material>
			</visual>
			<visual name='motor_L_visual'>
				<pose frame=''>.007 .002 .0505 0 -0 0</pose>
				<geometry>
					<mesh>
						<scale>1 1 1</scale>
						<uri>model://vant4/meshes/motor_L.STL</uri>
					</mesh>
				</geometry>
                <material>
                    <ambient>.6 .4 .2 1</ambient>
                    <diffuse>.6 .4 .2 1</diffuse>
                    <specular>1 1 1 1</specular>
                    <emissive>0 0 0 0</emissive>
                </material>
			</visual>
		</link>
		<joint name='joint_rotor_L' type='revolute'>
			<child>rotor_L</child>
			<parent>body</parent>
			<axis>
				<xyz>0 1 0</xyz>
				<limit>
					<lower>-1.5708</lower>
					<upper>1.5708</upper>
				</limit>
				<dynamics>
					<spring_reference>0</spring_reference>
					<spring_stiffness>0</spring_stiffness>
				</dynamics>
				<use_parent_model_frame>1</use_parent_model_frame>
			</axis>
		</joint>
		<link name='rotor_R'>
			<pose frame=''>0.077968 -0.60727 0.12348 0 -0 0</pose>
			<inertial>
				<pose frame=''>0.00493 0.001705 0.036854 0 -0 0</pose>
				<mass>0.51992</mass>
				<inertia>
					<ixx>0.0023933</ixx>
					<ixy>9.7215e-07</ixy>
					<ixz>-4.9353e-05</ixz>
					<iyy>0.0024969</iyy>
					<iyz>4.792e-06</iyz>
					<izz>0.00032972</izz>
				</inertia>
			</inertial>
			<collision name='rotor_R_collision'>
				<pose frame=''>0 0 0 0 -0 0</pose>
				<geometry>
					<mesh>
						<scale>1 1 1</scale>
						<uri>model://vant4/meshes/rotor_R.STL</uri>
					</mesh>
				</geometry>
			</collision>
			<collision name='motor_R_collision'>
				<pose frame=''>0 0 0 0 -0 0</pose>
				<geometry>
					<mesh>
						<scale>1 1 1</scale>
						<uri>model://vant4/meshes/motor_R.STL</uri>
					</mesh>
				</geometry>
			</collision>
			<visual name='rotor_R_visual'>
				<pose frame=''>0 0 0 0 -0 0</pose>
				<geometry>
					<mesh>
						<scale>1 1 1</scale>
						<uri>model://vant4/meshes/rotor_R.STL</uri>
					</mesh>
				</geometry>
                <material>
                    <ambient>.4 .4 .5 1</ambient>
                    <diffuse>.4 .4 .5 1</diffuse>
                    <specular>1 1 1 1</specular>
                    <emissive>0 0 0 0</emissive>
                </material>
			</visual>
			<visual name='motor_R_visual'>
				<pose frame=''>.007 .002 .0505 0 -0 0</pose>
				<geometry>
					<mesh>
						<scale>1 1 1</scale>
						<uri>model://vant4/meshes/motor_R.STL</uri>
					</mesh>
				</geometry>
                <material>
                    <ambient>.6 .4 .2 1</ambient>
                    <diffuse>.6 .4 .2 1</diffuse>
                    <specular>1 1 1 1</specular>
                    <emissive>0 0 0 0</emissive>
                </material>
			</visual>
		</link>
		<joint name='joint_rotor_R' type='revolute'>
			<child>rotor_R</child>
			<parent>body</parent>
			<axis>
				<xyz>0 1 0</xyz>
				<limit>
					<lower>-1.5708</lower>
					<upper>1.5708</upper>
				</limit>
				<dynamics>
					<spring_reference>0</spring_reference>
					<spring_stiffness>0</spring_stiffness>
				</dynamics>
				<use_parent_model_frame>1</use_parent_model_frame>
			</axis>
		</joint>
		<link name='rudder_L'>
			<pose frame=''>-0.40846 0.17214 0.14982 1.6893 -1.0594 -1.5708</pose>
			<inertial>
				<pose frame=''>0 -0.004612 0.008548 0 -0 0</pose>
				<mass>0.024834</mass>
				<inertia>
					<ixx>0.00012997</ixx>
					<ixy>1.3835e-10</ixy>
					<ixz>1.4834e-11</ixz>
					<iyy>1.0601e-06</iyy>
					<iyz>-6.1726e-07</iyz>
					<izz>0.00012902</izz>
				</inertia>
			</inertial>
			<collision name='rudder_L_collision'>
				<pose frame=''>0 0 0 0 -0 0</pose>
				<geometry>
					<mesh>
						<scale>1 1 1</scale>
						<uri>model://vant4/meshes/rudder_L.STL</uri>
					</mesh>
				</geometry>
			</collision>
			<visual name='rudder_L_visual'>
				<pose frame=''>0 0 0 0 -0 0</pose>
				<geometry>
					<mesh>
						<scale>1 1 1</scale>
						<uri>model://vant4/meshes/rudder_L.STL</uri>
					</mesh>
				</geometry>
                <material>
                    <ambient>.4 .4 .5 1</ambient>
                    <diffuse>.4 .4 .5 1</diffuse>
                    <specular>1 1 1 1</specular>
                    <emissive>0 0 0 0</emissive>
                </material>
			</visual>
		</link>
		<joint name='joint_rudder_L' type='revolute'>
			<child>rudder_L</child>
			<parent>body</parent>
			<axis>
				<xyz>-0.118223 0.865946 0.485963</xyz>
				<limit>
					<lower>-0.5</lower>
					<upper>0.5</upper>
				</limit>
				<dynamics>
					<spring_reference>0</spring_reference>
					<spring_stiffness>0</spring_stiffness>
				</dynamics>
				<use_parent_model_frame>1</use_parent_model_frame>
			</axis>
		</joint>
		<link name='rudder_R'>
			<pose frame=''>-0.40846 -0.17214 0.14982 -1.6893 -1.0594 1.5708</pose>
			<inertial>
				<pose frame=''>0 0.004612 0.008548 0 -0 0</pose>
				<mass>0.024834</mass>
				<inertia>
					<ixx>0.00012997</ixx>
					<ixy>-1.4419e-10</ixy>
					<ixz>1.552e-11</ixz>
					<iyy>1.0601e-06</iyy>
					<iyz>6.171e-07</iyz>
					<izz>0.00012902</izz>
				</inertia>
			</inertial>
			<collision name='rudder_R_collision'>
				<pose frame=''>0 0 0 0 -0 0</pose>
				<geometry>
					<mesh>
						<scale>1 1 1</scale>
						<uri>model://vant4/meshes/rudder_R.STL</uri>
					</mesh>
				</geometry>
			</collision>
			<visual name='rudder_R_visual'>
				<pose frame=''>0 0 0 0 -0 0</pose>
				<geometry>
					<mesh>
						<scale>1 1 1</scale>
						<uri>model://vant4/meshes/rudder_R.STL</uri>
					</mesh>
				</geometry>
                <material>
                    <ambient>.4 .4 .5 1</ambient>
                    <diffuse>.4 .4 .5 1</diffuse>
                    <specular>1 1 1 1</specular>
                    <emissive>0 0 0 0</emissive>
                </material>
			</visual>
		</link>
		<joint name='joint_rudder_R' type='revolute'>
			<child>rudder_R</child>
			<parent>body</parent>
			<axis>
				<xyz>0.118223 0.865946 -0.485963</xyz>
				<limit>
					<lower>-0.5</lower>
					<upper>0.5</upper>
				</limit>
				<dynamics>
					<spring_reference>0</spring_reference>
					<spring_stiffness>0</spring_stiffness>
				</dynamics>
				<use_parent_model_frame>1</use_parent_model_frame>
			</axis>
		</joint>

		<plugin name="plugin_thrust" filename="libgazebo_ros_brushless_plugin.so">
			<topic_FR> vant4/actuators/thrust_R </topic_FR>
			<topic_FL> vant4/actuators/thrust_L </topic_FL>
			<LinkDir> rotor_R </LinkDir>
			<LinkEsq> rotor_L </LinkEsq>
		</plugin>
		<plugin name="plugin_rotor_R" filename="libgazebo_ros_servo_motor_plugin.so">
			<NameOfJoint> joint_rotor_R </NameOfJoint>
			<TopicSubscriber> vant4/actuators/rotor_R </TopicSubscriber>
			<TopicPublisher> vant4/sensors/rotor_R </TopicPublisher>
            <ChildLink> rotor_R </ChildLink>
			<Modo> Posição </Modo>
		</plugin>
		<plugin name="plugin_rotor_L" filename="libgazebo_ros_servo_motor_plugin.so">
			<NameOfJoint> joint_rotor_L </NameOfJoint>
			<TopicSubscriber> vant4/actuators/rotor_L </TopicSubscriber>
			<TopicPublisher> vant4/sensors/rotor_L </TopicPublisher>
            <ChildLink> rotor_L </ChildLink>
			<Modo> Posição </Modo>
		</plugin>
		<plugin name="plugin_rudder_R" filename="libgazebo_ros_servo_motor_plugin.so">
			<NameOfJoint> joint_rudder_R </NameOfJoint>
			<TopicSubscriber> vant4/actuators/rudder_R </TopicSubscriber>
			<TopicPublisher> vant4/sensors/rudder_R </TopicPublisher>
            <ChildLink>rudder_R </ChildLink>
			<Modo> Posição </Modo>
		</plugin>
		<plugin name="plugin_rudder_L" filename="libgazebo_ros_servo_motor_plugin.so">
			<NameOfJoint> joint_rudder_L </NameOfJoint>
			<TopicSubscriber> vant4/actuators/rudder_L </TopicSubscriber>
			<TopicPublisher> vant4/sensors/rudder_L </TopicPublisher>
            <ChildLink> rudder_L </ChildLink>
			<Modo> Posição </Modo>
		</plugin>
		<plugin name="estados" filename="libgazebo_ros_AllData_plugin.so">
			<bodyName> body </bodyName>
			<NameOfTopic> vant4/sensors/estados </NameOfTopic>
			<NameOfJointR> joint_rotor_R </NameOfJointR>
			<NameOfJointL> joint_rotor_L </NameOfJointL>
		</plugin>
	</model>
</sdf>
