<sdf version='1.6'>
  <model name='vant3'>

    <link name='main_body'>
      <pose>0 0 0 0 -0 0</pose>

      <inertial>
        <!-- <pose>-0.028515 -0.000169 0.001696 0 -0 0</pose> -->
        <pose>0 0 0 0 -0 0</pose>
        
        <mass>1.49981</mass>
        <inertia>
          <ixx>0.0478834</ixx>
          <ixy>-1.54722e-05</ixy>
          <ixz>-0.00363249</ixz>
          <iyy>0.0227521</iyy>
          <iyz>8.22828e-06</iyz>
          <izz>0.0606231</izz>
        </inertia>
      </inertial>
      
      <collision name='main_body_collision'>
        <pose>0 0 0 0 -0 0</pose>
        <geometry>
          <mesh>
            <uri>model://vant_3.0/meshes/main_body.STL</uri>
          </mesh>
        </geometry>
      </collision>

      <visual name='main_body_visual'>
        <pose>0 0 0 0 -0 0</pose>
        <geometry>
          <mesh>
            <uri>model://vant_3.0/meshes/main_body.STL</uri>
          </mesh>
        </geometry>
        
        <material>
		<ambient>1 1 1 0.6 </ambient>
		<diffuse>1 1 1 0.6 </diffuse>
		<specular>1 1 1 0.6</specular>
		<emissive>0 0 0 0</emissive>
	</material>
				
      </visual>
    </link>
    
    <link name='motorL'>
      <pose>0.000595 0.270515 0.065905 0.069813 0 -0</pose>
      
      <inertial>
        <pose>7.4e-05 0.000504 0.05399 0 -0 0</pose>
        <mass>0.0747603</mass>
        <inertia>
          <ixx>4.04347e-05</ixx>
          <ixy>-8.14599e-08</ixy>
          <ixz>-1.01554e-07</ixz>
          <iyy>3.83961e-05</iyy>
          <iyz>-1.39683e-06</iyz>
          <izz>1.58679e-05</izz>
        </inertia>
      </inertial>
      
      <collision name='motorL_collision'>
        <pose>0 0 0 0 -0 0</pose>
        <geometry>
          <mesh>
            <uri>model://vant_3.0/meshes/motorL.STL</uri>
          </mesh>
        </geometry>
      </collision>
      
      <visual name='motorL_visual'>
        <pose>0 0 0 0 -0 0</pose>
        <geometry>
          <mesh>
            <uri>model://vant_3.0/meshes/motorL.STL</uri>
          </mesh>
        </geometry>
	<material>
                    <ambient>0 0 0 0</ambient>
                    <diffuse>1 1 1 1</diffuse>
                    <specular>0.1 0.1 0.1 1</specular>
                    <emissive>0 0 0 0</emissive>
                </material>
      </visual>
    </link>
    
    <joint name='aL' type='revolute'>
      <child>motorL</child>
      <parent>main_body</parent>
      <pose>0 0 0 0 0 0</pose>
      <axis>
        <xyz>0 0.997564 0.069757</xyz>

        <limit>
          <lower>-1.5</lower>
          <upper>1.5</upper>
          <effort>200</effort>
          <velocity>100</velocity>
        </limit>

        <dynamics>
                    <damping>0</damping>
                    <friction>0</friction>
                </dynamics>

        <use_parent_model_frame>1</use_parent_model_frame>
      </axis>
    </joint>
    
    <link name='propeller_L'>
      <pose>0.000595 0.270515 0.065905 0.069813 0 -0</pose>

      <inertial>
        <pose>-0 -0 0.084001 0 -0 0</pose>
        <mass>0.00963023</mass>
        <inertia>
          <ixx>7.75859e-07</ixx>
          <ixy>6.0309e-06</ixy>
          <ixz>2.12748e-11</ixz>
          <iyy>6.80092e-05</iyy>
          <iyz>3.21106e-12</iyz>
          <izz>6.8753e-05</izz>
        </inertia>
      </inertial>
      
      <collision name='propeller_L_collision'>
        <pose>0 0 0 0 -0 0</pose>
        <geometry>
          <mesh>
            <uri>model://vant_3.0/meshes/propeller_L.STL</uri>
          </mesh>
        </geometry>
      </collision>
      
      <visual name='propeller_L_visual'>
        <pose>0 0 0 0 -0 0</pose>
        <geometry>
          <mesh>
            <uri>model://vant_3.0/meshes/propeller_L.STL</uri>
          </mesh>
        </geometry>
        
        <material>
		<ambient>0 0 1 0.8 </ambient>
		<diffuse>0 0 1 0.8 </diffuse>
		<specular>0 0 1 0.8</specular>
		<emissive>0 0 0 0</emissive>
	</material>
				
      </visual>
    </link>

    <joint name='thrustesq' type='revolute'>
      <child>propeller_L</child>
      <parent>motorL</parent>
      <pose>0 0 0 0 0 0</pose>
      <axis>
        <xyz>-0 -0.069757 0.997564</xyz>
        <dynamics>
                    <damping>0</damping>
                    <friction>0</friction>
                </dynamics>

        <use_parent_model_frame>1</use_parent_model_frame>
      </axis>
    </joint>

    <link name='motorR'>
      <pose>0.000678 -0.270482 0.065905 -0.069813 0 -0</pose>
    
      <inertial>
        <pose>7.4e-05 -0.000357 0.05399 0 -0 0</pose>
        <mass>0.0747603</mass>
        <inertia>
          <ixx>4.04442e-05</ixx>
          <ixy>-7.67081e-08</ixy>
          <ixz>-1.01488e-07</ixz>
          <iyy>3.83961e-05</iyy>
          <iyz>1.19379e-06</iyz>
          <izz>1.58774e-05</izz>
        </inertia>
      </inertial>
    
      <collision name='motorR_collision'>
        <pose>0 0 0 0 -0 0</pose>
        <geometry>
          <mesh>
            <uri>model://vant_3.0/meshes/motorR.STL</uri>
          </mesh>
        </geometry>
      </collision>
    
      <visual name='motorR_visual'>
        <pose>0 0 0 0 -0 0</pose>
        <geometry>
          <mesh>
            <uri>model://vant_3.0/meshes/motorR.STL</uri>
          </mesh>
        </geometry>
        <material>
                    <ambient>0 0 0 0</ambient>
                    <diffuse>1 1 1 1</diffuse>
                    <specular>0.1 0.1 0.1 1</specular>
                    <emissive>0 0 0 0</emissive>
                </material>
      </visual>
    
    </link>
    
    <joint name='aR' type='revolute'>
      <child>motorR</child>
      <parent>main_body</parent>
      <pose>0 0 0 0 0 0</pose>
      <axis>
        <xyz>-0 0.997564 0.069757</xyz>
    
        <limit>
          <lower>-1.5</lower>
          <upper>1.5</upper>
          <effort>200</effort>
          <velocity>100</velocity>
        </limit>
    
        <dynamics>
                    <damping>0</damping>
                    <friction>0</friction>
                </dynamics>
    
        <use_parent_model_frame>1</use_parent_model_frame>
      </axis>
    </joint>

    <link name='propeller_R'>
      <pose>0.000678 -0.270482 0.065905 -0.069813 0 -0</pose>
	
      <inertial>
        <pose>0 0 0.084001 0 -0 0</pose>
        <mass>0.00963023</mass>

        <inertia>
          <ixx>7.75859e-07</ixx>
          <ixy>6.0309e-06</ixy>
          <ixz>-2.12748e-11</ixz>
          <iyy>6.80092e-05</iyy>
          <iyz>-3.21106e-12</iyz>
          <izz>6.8753e-05</izz>
        </inertia>
      </inertial>

     <collision name='propeller_R_collision'>
        <pose>0 0 0 0 -0 0</pose>
        <geometry>
          <mesh>
            <uri>model://vant_3.0/meshes/propeller_R.STL</uri>
          </mesh>
        </geometry>
      </collision>
      
      <visual name='propeller_R_visual'>
        <pose>0 0 0 0 -0 0</pose>
        <geometry>
          <mesh>
            <uri>model://vant_3.0/meshes/propeller_R.STL</uri>
          </mesh>
        </geometry>
        
        <material>
		<ambient>0 0 1 0.8 </ambient>
		<diffuse>0 0 1 0.8 </diffuse>
		<specular>0 0 1 0.8</specular>
		<emissive>0 0 0 0</emissive>
	</material>
				
      </visual>
    </link>

    <joint name='thrustdir' type='revolute'>
      <child>propeller_R</child>
      <parent>motorR</parent>
	<pose>0 0 0 0 0 0</pose>
      <axis>
        <xyz>0 0.069757 0.997564</xyz>
     
        <dynamics>
                    <damping>0</damping>
                    <friction>0</friction>
                </dynamics>
      </axis>
    </joint>

    <link name='elevator'>
      <pose>-0.415877 1.7e-05 0.11572 0 -0 -0</pose>
 
      <inertial>
        <pose>-0.006487 0 -2.9e-05 0 -0 0</pose>
        <mass>0.035036</mass>
        <inertia>
          <ixx>0.000144153</ixx>
          <ixy>-9.69613e-15</ixy>
          <ixz>5.83926e-09</ixz>
          <iyy>1.46871e-06</iyy>
          <iyz>2.13907e-12</iyz>
          <izz>0.000145438</izz>
        </inertia>
      </inertial>
    
      <collision name='elevator_collision'>
        <pose>0 0 0 0 -0 0</pose>
        <geometry>
          <mesh>
            <uri>model://vant_3.0/meshes/elevator.STL</uri>
          </mesh>
        </geometry>
      </collision>
    
      <visual name='elevator_visual'>
        <pose>0 0 0 0 -0 0</pose>
        <geometry>
          <mesh>
            <uri>model://vant_3.0/meshes/elevator.STL</uri>
          </mesh>
        </geometry>
        <material>
                    <ambient>0 0 0 0</ambient>
                    <diffuse>1 1 1 1</diffuse>
                    <specular>0.1 0.1 0.1 1</specular>
                    <emissive>0 0 0 0</emissive>
                </material>
      </visual>
    </link>
    
    <joint name='elev' type='revolute'>
      <child>elevator</child>
      <parent>main_body</parent>
      <pose>0 0 0 0 0 0</pose>
      <axis>
        <xyz>0 1 0</xyz>
      
        <limit>
          <lower>-0.5</lower>
          <upper>0.5</upper>
          <effort>200</effort>
          <velocity>100</velocity>
        </limit>
      
        <dynamics>
                    <damping>0</damping>
                    <friction>0</friction>
                </dynamics>
      
      </axis>
    </joint>

    <link name='rudder'>
      <pose>-0.372208 4e-05 0.019995 -0.00264 -0.319337 -0</pose>
    
      <inertial>
        <pose>-0.006452 5.2e-05 0.011519 0 -0 0</pose>
        <mass>0.0189643</mass>
        <inertia>
          <ixx>3.56832e-05</ixx>
          <ixy>-1.14682e-08</ixy>
          <ixz>-5.25781e-07</ixz>
          <iyy>3.71206e-05</iyy>
          <iyz>4.19428e-09</iyz>
          <izz>1.50029e-06</izz>
        </inertia>
      </inertial>
    
      <collision name='rudder_collision'>
        <pose>0 0 0 0 -0 0</pose>
        <geometry>
          <mesh>
            <uri>model://vant_3.0/meshes/rudder.STL</uri>
          </mesh>
        </geometry>
      </collision>
    
      <visual name='rudder_visual'>
        <pose>0 0 0 0 -0 0</pose>
        <geometry>
          <mesh>
            <uri>model://vant_3.0/meshes/rudder.STL</uri>
          </mesh>
        </geometry>
        <material>
                    <ambient>0 0 0 0</ambient>
                    <diffuse>1 1 1 1</diffuse>
                    <specular>0.1 0.1 0.1 1</specular>
                    <emissive>0 0 0 0</emissive>
                </material>
      </visual>
    </link>
    
    <joint name='rud' type='revolute'>
      <child>rudder</child>
      <parent>main_body</parent>
      <pose>0 0 0 0 0 0</pose>
      <axis>
        <xyz>0.313936 -0.00264 -0.94944</xyz>
        <limit>
          <lower>-0.5</lower>
          <upper>0.5</upper>
          <effort>200</effort>
          <velocity>100</velocity>
        </limit>
    
        <dynamics>
                    <damping>0</damping>
                    <friction>0</friction>
                </dynamics>
    
      </axis>
    </joint>



    <plugin filename="libgazebo_ros_servo_motor_plugin.so" name="aLplugin"> 
      <NameOfJoint> aL </NameOfJoint> 
      <Modo> Torque </Modo> 
      <TopicSubscriber> TauL </TopicSubscriber> 
      <TopicPublisher> SensoraL </TopicPublisher> 
    </plugin> 

    <plugin filename="libgazebo_ros_servo_motor_plugin.so" name="aRplugin"> 
      <NameOfJoint> aR </NameOfJoint> 
      <Modo> Torque </Modo> 
      <TopicSubscriber> TauR </TopicSubscriber> 
      <TopicPublisher> SensoraR </TopicPublisher> 
    </plugin> 

    <plugin filename="libgazebo_ros_servo_motor_plugin.so" name="rudplugin">
      <NameOfJoint> rud </NameOfJoint>
      <Modo> Posicao </Modo>
      <TopicSubscriber> Ruddef </TopicSubscriber>
      <TopicPublisher> SensorRud </TopicPublisher>
    </plugin>

    <plugin filename="libgazebo_ros_servo_motor_plugin.so" name="elevplugin">
      <NameOfJoint> elev </NameOfJoint>
      <Modo> Posicao </Modo>
      <TopicSubscriber> Elevdef </TopicSubscriber>
      <TopicPublisher> SensorElev </TopicPublisher>
    </plugin>

    <plugin filename="libgazebo_ros_AllData_plugin.so" name="VetorEstados">   
       <bodyName> main_body </bodyName> 
       <NameOfNode> Estados </NameOfNode> 
       <NameOfJointR> aR </NameOfJointR> 
       <NameOfJointL> aL </NameOfJointL> 
     </plugin>  
    
     <plugin filename="libgazebo_ros_aerodinamica_plugin.so" name="empuxo">            
       <bodyName> main_body </bodyName> 
       <NameOfNode> Estados </NameOfNode> 
      
       <topic_Fr> ThrustR </topic_Fr> 
       <LinkFr> propeller_R </LinkFr> 
       <JointFr>  thrustdir  </JointFr> 

       <topic_Fl> ThrustL </topic_Fl> 
       <LinkFl> propeller_L </LinkFl> 
       <JointFl>  thrustesq  </JointFl> 

       <topic_Rud> posRud </topic_Rud> 
       <LinkRud> rudder </LinkRud> 
      
       <topic_Elev> posElev </topic_Elev> 
       <LinkElev> elevator </LinkElev> 
     </plugin> 

   </model> 
 </sdf> 


















































