<?xml version="1.0" encoding="UTF-8"?>
<!--
This file is part of the ProVANT simulator project.
Licensed under the terms of the MIT open source license. More details at
https://github.com/Guiraffo/ProVANT-Simulator/blob/master/LICENSE.md
-->
<robot name="vant_5_aerod">
  <link name="main_body">
    <inertial>
      <origin xyz="-0.078058 0 -0.12418" rpy="0 0 0" />
      <mass value="19.067" />
      <inertia ixx="0.44425" ixy="0" ixz="-0.1429" iyy="1.2557" iyz="0" izz="1.6146" />
    </inertial>
    <visual>
      <origin xyz="0 0 0" rpy="0 0 0" />
      <geometry>
        <mesh filename="package://vant_5_aerod/meshes/main_body.STL" />
      </geometry>
      <material name="">
        <color rgba="0.95294 0.99608 0.69412 1" />
      </material>
    </visual>
    <collision>
      <origin xyz="0 0 0" rpy="0 0 0" />
      <geometry>
        <mesh filename="package://vant_5_aerod/meshes/main_body.STL" />
      </geometry>
    </collision>
  </link>
  <link name="rotorCm2">
    <inertial>
      <origin xyz="0 0 -0.0045697" rpy="0 0 0" />
      <mass value="0.51926" />
      <inertia ixx="0.0022642" ixy="0" ixz="0" iyy="0.0022651" iyz="0" izz="0.00041063" />
    </inertial>
    <visual>
      <origin xyz="0 0 0" rpy="0 0 0" />
      <geometry>
        <mesh filename="package://vant_5_aerod/meshes/rotorCm2.STL" />
      </geometry>
      <material name="">
        <color rgba="0.95294 0.99608 0.69412 1" />
      </material>
    </visual>
    <collision>
      <origin xyz="0 0 0" rpy="0 0 0" />
      <geometry>
        <mesh filename="package://vant_5_aerod/meshes/rotorCm2.STL" />
      </geometry>
    </collision>
  </link>
  <joint name="rotationCm2" type="revolute">
    <origin xyz="0.47527 -0.375 -0.10177" rpy="0 0 0" />
    <parent link="main_body" />
    <child link="rotorCm2" />
    <axis xyz="0 1 0" />
    <limit lower="-1.57" upper="1.57" effort="0" velocity="0" />
  </joint>
  <link name="proppeller2">
    <inertial>
      <origin xyz="0.00060272 4.4009E-05 -0.074568" rpy="0 0 0" />
      <mass value="0.02" />
      <inertia ixx="0.0022644" ixy="2.5331E-07" ixz="1.4153E-05" iyy="0.0022649" iyz="-1.2481E-07" izz="0.00041063" />
    </inertial>
    <visual>
      <origin xyz="0 0 0" rpy="0 0 0" />
      <geometry>
        <mesh filename="package://vant_5_aerod/meshes/proppeller2.STL" />
      </geometry>
      <material name="">
        <color rgba="0.95294 0.99608 0.69412 1" />
      </material>
    </visual>
    <collision>
      <origin xyz="0 0 0" rpy="0 0 0" />
      <geometry>
        <mesh filename="package://vant_5_aerod/meshes/proppeller2.STL" />
      </geometry>
    </collision>
  </link>
  <joint name="joint_rotor2prop2" type="revolute">
    <origin xyz="-0.0005434 0 0.069998" rpy="0 0 0" />
    <parent link="rotorCm2" />
    <child link="proppeller2" />
    <axis xyz="0.0077629 0 -0.99997" />
    <limit lower="-3.1416" upper="3.1416" effort="0" velocity="0" />
  </joint>
  <link name="rotorCm3">
    <inertial>
      <origin xyz="0 0 -0.0045589" rpy="0 0 0" />
      <mass value="0.51927" />
      <inertia ixx="0.0022563" ixy="0" ixz="0.00012277" iyy="0.0022653" iyz="0" izz="0.00041886" />
    </inertial>
    <visual>
      <origin xyz="0 0 0" rpy="0 0 0" />
      <geometry>
        <mesh filename="package://vant_5_aerod/meshes/rotorCm3.STL" />
      </geometry>
      <material name="">
        <color rgba="0.95294 0.99608 0.69412 1" />
      </material>
    </visual>
    <collision>
      <origin xyz="0 0 0" rpy="0 0 0" />
      <geometry>
        <mesh filename="package://vant_5_aerod/meshes/rotorCm3.STL" />
      </geometry>
    </collision>
  </link>
  <joint name="rotationCm3" type="revolute">
    <origin xyz="0.47527 0.375 -0.10177" rpy="0 0 0" />
    <parent link="main_body" />
    <child link="rotorCm3" />
    <axis xyz="0 -1 0" />
    <limit lower="-1.57" upper="1.57" effort="0" velocity="0" />
  </joint>
  <link name="proppeler3">
    <inertial>
      <origin xyz="0.0049643 -4.3624E-05 -0.074402" rpy="0 0 0" />
      <mass value="0.02" />
      <inertia ixx="0.0022565" ixy="-2.3963E-07" ixz="0.00012245" iyy="0.0022651" iyz="2.6894E-08" izz="0.00041885" />
    </inertial>
    <visual>
      <origin xyz="0 0 0" rpy="0 0 0" />
      <geometry>
        <mesh filename="package://vant_5_aerod/meshes/proppeler3.STL" />
      </geometry>
      <material name="">
        <color rgba="0.95294 0.99608 0.69412 1" />
      </material>
    </visual>
    <collision>
      <origin xyz="0 0 0" rpy="0 0 0" />
      <geometry>
        <mesh filename="package://vant_5_aerod/meshes/proppeler3.STL" />
      </geometry>
    </collision>
  </link>
  <joint name="joint_rotor3prop3" type="revolute">
    <origin xyz="-0.00464240385383174 0 0.0698458881141759" rpy="0 0 0" />
    <parent link="rotorCm3" />
    <child link="proppeler3" />
    <axis xyz="0.0663200550547391 0 -0.997798401631079" />
    <limit lower="-3.1416" upper="3.1416" effort="0" velocity="0" />
  </joint>
  <link name="rotorCm4">
    <inertial>
      <origin xyz="-0.017875 0 -0.083521" rpy="0 0 0" />
      <mass value="1.0763" />
      <inertia ixx="0.0093551" ixy="0" ixz="0.0012177" iyy="0.012026" iyz="0" izz="0.0032113" />
    </inertial>
    <visual>
      <origin xyz="0 0 0" rpy="0 0 0" />
      <geometry>
        <mesh filename="package://vant_5_aerod/meshes/rotorCm4.STL" />
      </geometry>
      <material name="">
        <color rgba="0.95294 0.99608 0.69412 1" />
      </material>
    </visual>
    <collision>
      <origin xyz="0 0 0" rpy="0 0 0" />
      <geometry>
        <mesh filename="package://vant_5_aerod/meshes/rotorCm4.STL" />
      </geometry>
    </collision>
  </link>
  <joint name="rotationCm4" type="revolute">
    <origin xyz="-0.31213 -0.57 0.010512" rpy="0 0 0" />
    <parent link="main_body" />
    <child link="rotorCm4" />
    <axis xyz="0 1 0" />
    <limit lower="-1.57" upper="1.57" effort="0" velocity="0" />
  </joint>
  <link name="proppeller4">
    <inertial>
      <origin xyz="-0.0043765 0.017222 -0.15355" rpy="0 0 0" />
      <mass value="0.02" />
      <inertia ixx="0.011887" ixy="0.00059442" ixz="-0.00029665" iyy="0.0094994" iyz="0.0011697" izz="0.0032078" />
    </inertial>
    <visual>
      <origin xyz="0 0 0" rpy="0 0 0" />
      <geometry>
        <mesh filename="package://vant_5_aerod/meshes/proppeller4.STL" />
      </geometry>
      <material name="">
        <color rgba="0.95294 0.99608 0.69412 1" />
      </material>
    </visual>
    <collision>
      <origin xyz="0 0 0" rpy="0 0 0" />
      <geometry>
        <mesh filename="package://vant_5_aerod/meshes/proppeller4.STL" />
      </geometry>
    </collision>
  </link>
  <joint name="joint_rotor4prop4" type="revolute">
    <origin xyz="0.00016905918442589 0 0.0699997958496448" rpy="0 0 0" />
    <parent link="rotorCm4" />
    <child link="proppeller4" />
    <axis xyz="-0.00241513120605813 0 -0.999997083566376" />
    <limit lower="-3.1416" upper="3.1416" effort="0" velocity="0" />
  </joint>
  <link name="rotorCm5">
    <inertial>
      <origin xyz="-0.017875 0 -0.083521" rpy="0 0 0" />
      <mass value="1.076" />
      <inertia ixx="0.0093551" ixy="0" ixz="0.0012177" iyy="0.012026" iyz="0" izz="0.0032113" />
    </inertial>
    <visual>
      <origin xyz="0 0 0" rpy="0 0 0" />
      <geometry>
        <mesh filename="package://vant_5_aerod/meshes/rotorCm5.STL" />
      </geometry>
      <material name="">
        <color rgba="0.95294 0.99608 0.69412 1" />
      </material>
    </visual>
    <collision>
      <origin xyz="0 0 0" rpy="0 0 0" />
      <geometry>
        <mesh filename="package://vant_5_aerod/meshes/rotorCm5.STL" />
      </geometry>
    </collision>
  </link>
  <joint name="rotationCm5" type="revolute">
    <origin xyz="-0.31213 0.57 0.010512" rpy="0 0 0" />
    <parent link="main_body" />
    <child link="rotorCm5" />
    <axis xyz="0 -1 0" />
    <limit lower="-1.57" upper="1.57" effort="0" velocity="0" />
  </joint>
  <link name="proppeller5">
    <inertial>
      <origin xyz="-0.0043765 0.017222 -0.15355" rpy="0 0 0" />
      <mass value="0.02" />
      <inertia ixx="0.011887" ixy="0.00059442" ixz="-0.00029665" iyy="0.0094994" iyz="0.0011697" izz="0.0032078" />
    </inertial>
    <visual>
      <origin xyz="0 0 0" rpy="0 0 0" />
      <geometry>
        <mesh filename="package://vant_5_aerod/meshes/proppeller5.STL" />
      </geometry>
      <material name="">
        <color rgba="0.95294 0.99608 0.69412 1" />
      </material>
    </visual>
    <collision>
      <origin xyz="0 0 0" rpy="0 0 0" />
      <geometry>
        <mesh filename="package://vant_5_aerod/meshes/proppeller5.STL" />
      </geometry>
    </collision>
  </link>
  <joint name="joint_rotor5prop5" type="revolute">
    <origin xyz="0.000403937556759715 0 0.0699988345220843" rpy="0 0 0" />
    <parent link="rotorCm5" />
    <child link="proppeller5" />
    <axis xyz="-0.00577053652512141 0 -0.9999833503155" />
    <limit lower="-3.1416" upper="3.1416" effort="0" velocity="0" />
  </joint>
</robot>